2021-07-12 09:45:19,543 : getLog.py : ERROR : Traceback (most recent call last):
  File "/Users/liushiwen/PycharmProjects/MyTestFramwoek/Common/getLog.py", line 71, in func
    num_sum = num1 * num2
TypeError: can't multiply sequence by non-int of type 'str'

2021-07-12 09:45:19,543 : getLog.py : ERROR : can't multiply sequence by non-int of type 'str'
2021-07-12 09:45:41,609 : getLog.py : ERROR : can't multiply sequence by non-int of type 'str'
2021-07-12 09:46:19,067 : getLog.py : ERROR : can't multiply sequence by non-int of type 'str'
2021-07-12 09:47:15,672 : getLog.py : ERROR : can't multiply sequence by non-int of type 'str'
2021-07-12 10:06:57,477 : getLog.py : ERROR : can't multiply sequence by non-int of type 'str'
2021-07-12 10:09:14,528 : getLog.py : ERROR : Traceback (most recent call last):
  File "/Users/liushiwen/PycharmProjects/MyTestFramwoek/Common/getLog.py", line 82, in func
    num_sum = num1 * num2
TypeError: can't multiply sequence by non-int of type 'str'

2021-07-12 10:13:06,535 : getLog.py : ERROR : Traceback (most recent call last):
  File "/Users/liushiwen/PycharmProjects/MyTestFramwoek/Common/getLog.py", line 82, in func
    num_sum = num1 * num2
TypeError: can't multiply sequence by non-int of type 'str'

2021-07-12 10:13:34,319 : getLog.py : CRITICAL : Traceback (most recent call last):
  File "/Users/liushiwen/PycharmProjects/MyTestFramwoek/Common/getLog.py", line 82, in func
    num_sum = num1 * num2
TypeError: can't multiply sequence by non-int of type 'str'

2021-07-12 10:49:22,324 : getVerificationCode.py : ERROR : Traceback (most recent call last):
  File "/Users/liushiwen/PycharmProjects/MyTestFramwoek/Common/getVerificationCode.py", line 43, in get_code_img_path
    code_location = self.driver.find_element(self.locationType,self.locatorExpression)
  File "/Users/liushiwen/.local/lib/python3.8/site-packages/selenium/webdriver/remote/webdriver.py", line 976, in find_element
    return self.execute(Command.FIND_ELEMENT, {
  File "/Users/liushiwen/.local/lib/python3.8/site-packages/selenium/webdriver/remote/webdriver.py", line 321, in execute
    self.error_handler.check_response(response)
  File "/Users/liushiwen/.local/lib/python3.8/site-packages/selenium/webdriver/remote/errorhandler.py", line 242, in check_response
    raise exception_class(message, screen, stacktrace)
selenium.common.exceptions.NoSuchElementException: Message: no such element: Unable to locate element: {"method":"css selector","selector":"[id="captcha-imgs"]"}
  (Session info: chrome=91.0.4472.114)


2021-07-12 10:52:35,194 : getVerificationCode.py : ERROR : Traceback (most recent call last):
  File "/Users/liushiwen/PycharmProjects/MyTestFramwoek/Common/getVerificationCode.py", line 43, in get_code_img_path
    code_location = self.driver.find_element(self.locationType,self.locatorExpression)
  File "/Users/liushiwen/.local/lib/python3.8/site-packages/selenium/webdriver/remote/webdriver.py", line 976, in find_element
    return self.execute(Command.FIND_ELEMENT, {
  File "/Users/liushiwen/.local/lib/python3.8/site-packages/selenium/webdriver/remote/webdriver.py", line 321, in execute
    self.error_handler.check_response(response)
  File "/Users/liushiwen/.local/lib/python3.8/site-packages/selenium/webdriver/remote/errorhandler.py", line 242, in check_response
    raise exception_class(message, screen, stacktrace)
selenium.common.exceptions.NoSuchElementException: Message: no such element: Unable to locate element: {"method":"css selector","selector":"[id="captcha-imgs"]"}
  (Session info: chrome=91.0.4472.114)


2021-07-12 10:54:52,877 : getVerificationCode.py : ERROR : Traceback (most recent call last):
  File "/Users/liushiwen/PycharmProjects/MyTestFramwoek/Common/getVerificationCode.py", line 43, in get_code_img_path
    code_location = self.driver.find_element(self.locationType,self.locatorExpression)
  File "/Users/liushiwen/.local/lib/python3.8/site-packages/selenium/webdriver/remote/webdriver.py", line 976, in find_element
    return self.execute(Command.FIND_ELEMENT, {
  File "/Users/liushiwen/.local/lib/python3.8/site-packages/selenium/webdriver/remote/webdriver.py", line 321, in execute
    self.error_handler.check_response(response)
  File "/Users/liushiwen/.local/lib/python3.8/site-packages/selenium/webdriver/remote/errorhandler.py", line 242, in check_response
    raise exception_class(message, screen, stacktrace)
selenium.common.exceptions.NoSuchElementException: Message: no such element: Unable to locate element: {"method":"xpath","selector":"captcha-img"}
  (Session info: chrome=91.0.4472.114)


2021-07-12 10:56:47,951 : getVerificationCode.py : ERROR : Traceback (most recent call last):
  File "/Users/liushiwen/PycharmProjects/MyTestFramwoek/Common/getVerificationCode.py", line 44, in get_code_img_path
    code_location = self.driver.find_element(self.locationType,self.locatorExpression)
  File "/Users/liushiwen/.local/lib/python3.8/site-packages/selenium/webdriver/remote/webdriver.py", line 976, in find_element
    return self.execute(Command.FIND_ELEMENT, {
  File "/Users/liushiwen/.local/lib/python3.8/site-packages/selenium/webdriver/remote/webdriver.py", line 321, in execute
    self.error_handler.check_response(response)
  File "/Users/liushiwen/.local/lib/python3.8/site-packages/selenium/webdriver/remote/errorhandler.py", line 242, in check_response
    raise exception_class(message, screen, stacktrace)
selenium.common.exceptions.NoSuchElementException: Message: no such element: Unable to locate element: {"method":"css selector","selector":"[id="captcha-imgs"]"}
  (Session info: chrome=91.0.4472.114)


2021-07-12 11:07:45,384 : operateMysql.py : ERROR : Traceback (most recent call last):
  File "/Users/liushiwen/PycharmProjects/MyTestFramwoek/Common/operateMysql.py", line 26, in __init__
    self._conn = pymysql.connect(host=self._host, user=self._user, password=self._password,
  File "/Users/liushiwen/miniforge3/envs/py38/lib/python3.8/site-packages/pymysql/connections.py", line 353, in __init__
    self.connect()
  File "/Users/liushiwen/miniforge3/envs/py38/lib/python3.8/site-packages/pymysql/connections.py", line 633, in connect
    self._request_authentication()
  File "/Users/liushiwen/miniforge3/envs/py38/lib/python3.8/site-packages/pymysql/connections.py", line 932, in _request_authentication
    auth_packet = _auth.caching_sha2_password_auth(self, auth_packet)
  File "/Users/liushiwen/miniforge3/envs/py38/lib/python3.8/site-packages/pymysql/_auth.py", line 266, in caching_sha2_password_auth
    pkt = _roundtrip(conn, data)
  File "/Users/liushiwen/miniforge3/envs/py38/lib/python3.8/site-packages/pymysql/_auth.py", line 120, in _roundtrip
    pkt = conn._read_packet()
  File "/Users/liushiwen/miniforge3/envs/py38/lib/python3.8/site-packages/pymysql/connections.py", line 725, in _read_packet
    packet.raise_for_error()
  File "/Users/liushiwen/miniforge3/envs/py38/lib/python3.8/site-packages/pymysql/protocol.py", line 221, in raise_for_error
    err.raise_mysql_exception(self._data)
  File "/Users/liushiwen/miniforge3/envs/py38/lib/python3.8/site-packages/pymysql/err.py", line 143, in raise_mysql_exception
    raise errorclass(errno, errval)
pymysql.err.OperationalError: (1045, "Access denied for user 'root'@'localhost' (using password: YES)")

2021-07-12 11:09:21,668 : operateMysql.py : ERROR : 请检查传入数据库参数是否正确
2021-07-12 11:09:21,669 : operateMysql.py : ERROR : Traceback (most recent call last):
  File "/Users/liushiwen/PycharmProjects/MyTestFramwoek/Common/operateMysql.py", line 26, in __init__
    self._conn = pymysql.connect(host=self._host, user=self._user, password=self._password,
  File "/Users/liushiwen/miniforge3/envs/py38/lib/python3.8/site-packages/pymysql/connections.py", line 353, in __init__
    self.connect()
  File "/Users/liushiwen/miniforge3/envs/py38/lib/python3.8/site-packages/pymysql/connections.py", line 633, in connect
    self._request_authentication()
  File "/Users/liushiwen/miniforge3/envs/py38/lib/python3.8/site-packages/pymysql/connections.py", line 932, in _request_authentication
    auth_packet = _auth.caching_sha2_password_auth(self, auth_packet)
  File "/Users/liushiwen/miniforge3/envs/py38/lib/python3.8/site-packages/pymysql/_auth.py", line 266, in caching_sha2_password_auth
    pkt = _roundtrip(conn, data)
  File "/Users/liushiwen/miniforge3/envs/py38/lib/python3.8/site-packages/pymysql/_auth.py", line 120, in _roundtrip
    pkt = conn._read_packet()
  File "/Users/liushiwen/miniforge3/envs/py38/lib/python3.8/site-packages/pymysql/connections.py", line 725, in _read_packet
    packet.raise_for_error()
  File "/Users/liushiwen/miniforge3/envs/py38/lib/python3.8/site-packages/pymysql/protocol.py", line 221, in raise_for_error
    err.raise_mysql_exception(self._data)
  File "/Users/liushiwen/miniforge3/envs/py38/lib/python3.8/site-packages/pymysql/err.py", line 143, in raise_mysql_exception
    raise errorclass(errno, errval)
pymysql.err.OperationalError: (1045, "Access denied for user 'root'@'localhost' (using password: YES)")

2021-07-12 11:26:44,816 : operateMysql.py : ERROR : SQL错误，请检查SQL格式是否正确
2021-07-12 11:26:44,817 : operateMysql.py : ERROR : Traceback (most recent call last):
  File "/Users/liushiwen/PycharmProjects/MyTestFramwoek/Common/operateMysql.py", line 52, in singleQuerySQL
    cur.execute(sql)
  File "/Users/liushiwen/miniforge3/envs/py38/lib/python3.8/site-packages/pymysql/cursors.py", line 148, in execute
    result = self._query(query)
  File "/Users/liushiwen/miniforge3/envs/py38/lib/python3.8/site-packages/pymysql/cursors.py", line 310, in _query
    conn.query(q)
  File "/Users/liushiwen/miniforge3/envs/py38/lib/python3.8/site-packages/pymysql/connections.py", line 548, in query
    self._affected_rows = self._read_query_result(unbuffered=unbuffered)
  File "/Users/liushiwen/miniforge3/envs/py38/lib/python3.8/site-packages/pymysql/connections.py", line 775, in _read_query_result
    result.read()
  File "/Users/liushiwen/miniforge3/envs/py38/lib/python3.8/site-packages/pymysql/connections.py", line 1156, in read
    first_packet = self.connection._read_packet()
  File "/Users/liushiwen/miniforge3/envs/py38/lib/python3.8/site-packages/pymysql/connections.py", line 725, in _read_packet
    packet.raise_for_error()
  File "/Users/liushiwen/miniforge3/envs/py38/lib/python3.8/site-packages/pymysql/protocol.py", line 221, in raise_for_error
    err.raise_mysql_exception(self._data)
  File "/Users/liushiwen/miniforge3/envs/py38/lib/python3.8/site-packages/pymysql/err.py", line 143, in raise_mysql_exception
    raise errorclass(errno, errval)
pymysql.err.ProgrammingError: (1064, "You have an error in your SQL syntax; check the manual that corresponds to your MySQL server version for the right syntax to use near 'use limit 2' at line 1")

2021-07-13 13:46:28,613 : operateExcel.py : ERROR : 文件路径不存在，请检查路径是否正确
2021-07-13 13:46:28,614 : operateExcel.py : ERROR : NoneType: None

2021-07-13 13:47:04,890 : operateExcel.py : ERROR : 文件路径不存在，请检查路径是否正确
2021-07-13 13:47:04,890 : operateExcel.py : ERROR : <class 'FileNotFoundError'>
2021-07-13 13:47:40,383 : operateExcel.py : ERROR : 文件路径不存在，请检查路径是否正确
2021-07-13 13:48:13,990 : operateExcel.py : ERROR : 请检查传入sheet是否存在
2021-07-15 09:18:18,186 : getLog.py : ERROR : Traceback (most recent call last):
  File "/Users/liushiwen/PycharmProjects/MyTestFramwoek/Common/getLog.py", line 82, in func
    num_sum = num1 * num2
TypeError: can't multiply sequence by non-int of type 'str'

2021-07-15 10:52:30,657 : sendEmail.py : ERROR : Traceback (most recent call last):
  File "/Users/liushiwen/PycharmProjects/MyTestFramwoek/Common/sendEmail.py", line 53, in mail_message
    with open(file=self.content_html_file, mode="r", encoding="utf-8") as file:
FileNotFoundError: [Errno 2] No such file or directory: '2020-05-20-23_11_43_result.html'

2021-07-15 10:52:30,657 : sendEmail.py : ERROR : Traceback (most recent call last):
  File "/Users/liushiwen/PycharmProjects/MyTestFramwoek/Common/sendEmail.py", line 62, in mail_message
    'content_html': self.content_html,
AttributeError: 'SendEmail' object has no attribute 'content_html'

2021-07-15 10:52:30,658 : sendEmail.py : ERROR : Traceback (most recent call last):
  File "/Users/liushiwen/PycharmProjects/MyTestFramwoek/Common/sendEmail.py", line 92, in send_email
    self.server.send_mail(recipients=recipients_info,cc=carbon_copy_info,mail=self.msg)
  File "/Users/liushiwen/.local/lib/python3.8/site-packages/zmail/server.py", line 96, in send_mail
    _mail = Mail(mail, debug=self.debug, log=self.log)
  File "/Users/liushiwen/.local/lib/python3.8/site-packages/zmail/mime.py", line 27, in __init__
    raise InvalidArguments('mail field excepted type dict or CaseInsensitiveDict got {}'.format(type(mail)))
zmail.exceptions.InvalidArguments: mail field excepted type dict or CaseInsensitiveDict got <class 'NoneType'>

2021-07-15 15:04:03,537 : browser.py : ERROR : 仅支持firefox, chrome, ie, phantomjs!
2021-07-15 15:04:03,537 : browser.py : ERROR : NoneType: None

2021-07-15 15:04:33,271 : browser.py : ERROR : NoneType: None

2021-07-15 15:04:47,179 : browser.py : ERROR : 仅支持firefox, chrome, ie, phantomjs!
2021-07-15 15:07:54,116 : browser.py : ERROR : 请检查url是否传入
2021-07-15 15:07:54,128 : browser.py : ERROR : Traceback (most recent call last):
  File "/Users/liushiwen/PycharmProjects/MyTestFramwoek/Common/browser.py", line 35, in get
    self.driver.get(url)
  File "/Users/liushiwen/.local/lib/python3.8/site-packages/selenium/webdriver/remote/webdriver.py", line 333, in get
    self.execute(Command.GET, {'url': url})
  File "/Users/liushiwen/.local/lib/python3.8/site-packages/selenium/webdriver/remote/webdriver.py", line 321, in execute
    self.error_handler.check_response(response)
  File "/Users/liushiwen/.local/lib/python3.8/site-packages/selenium/webdriver/remote/errorhandler.py", line 242, in check_response
    raise exception_class(message, screen, stacktrace)
selenium.common.exceptions.InvalidArgumentException: Message: invalid argument: 'url' must be a string
  (Session info: chrome=91.0.4472.114)


2021-07-15 15:27:57,701 : client.py : ERROR : 不支持的method:HAHA，请检查传入参数！
2021-07-16 11:02:09,966 : APIMethodEntrance.py : ERROR : Traceback (most recent call last):
  File "/Users/liushiwen/PycharmProjects/MyTestFramwoek/KernelEntrace/APIMethodEntrance.py", line 13, in func
    num_sum = num1 * num2
TypeError: can't multiply sequence by non-int of type 'str'

