2021-07-12 09:45:19,543 : getLog.py : ERROR : Traceback (most recent call last):
  File "/Users/liushiwen/PycharmProjects/MyTestFramwoek/Common/getLog.py", line 71, in func
    num_sum = num1 * num2
TypeError: can't multiply sequence by non-int of type 'str'

2021-07-12 09:45:19,543 : getLog.py : ERROR : can't multiply sequence by non-int of type 'str'
2021-07-12 09:45:41,609 : getLog.py : ERROR : can't multiply sequence by non-int of type 'str'
2021-07-12 09:46:19,067 : getLog.py : ERROR : can't multiply sequence by non-int of type 'str'
2021-07-12 09:47:15,672 : getLog.py : ERROR : can't multiply sequence by non-int of type 'str'
2021-07-12 10:06:57,477 : getLog.py : ERROR : can't multiply sequence by non-int of type 'str'
2021-07-12 10:09:14,528 : getLog.py : ERROR : Traceback (most recent call last):
  File "/Users/liushiwen/PycharmProjects/MyTestFramwoek/Common/getLog.py", line 82, in func
    num_sum = num1 * num2
TypeError: can't multiply sequence by non-int of type 'str'

2021-07-12 10:13:06,535 : getLog.py : ERROR : Traceback (most recent call last):
  File "/Users/liushiwen/PycharmProjects/MyTestFramwoek/Common/getLog.py", line 82, in func
    num_sum = num1 * num2
TypeError: can't multiply sequence by non-int of type 'str'

2021-07-12 10:13:34,319 : getLog.py : CRITICAL : Traceback (most recent call last):
  File "/Users/liushiwen/PycharmProjects/MyTestFramwoek/Common/getLog.py", line 82, in func
    num_sum = num1 * num2
TypeError: can't multiply sequence by non-int of type 'str'

2021-07-12 10:49:22,324 : getVerificationCode.py : ERROR : Traceback (most recent call last):
  File "/Users/liushiwen/PycharmProjects/MyTestFramwoek/Common/getVerificationCode.py", line 43, in get_code_img_path
    code_location = self.driver.find_element(self.locationType,self.locatorExpression)
  File "/Users/liushiwen/.local/lib/python3.8/site-packages/selenium/webdriver/remote/webdriver.py", line 976, in find_element
    return self.execute(Command.FIND_ELEMENT, {
  File "/Users/liushiwen/.local/lib/python3.8/site-packages/selenium/webdriver/remote/webdriver.py", line 321, in execute
    self.error_handler.check_response(response)
  File "/Users/liushiwen/.local/lib/python3.8/site-packages/selenium/webdriver/remote/errorhandler.py", line 242, in check_response
    raise exception_class(message, screen, stacktrace)
selenium.common.exceptions.NoSuchElementException: Message: no such element: Unable to locate element: {"method":"css selector","selector":"[id="captcha-imgs"]"}
  (Session info: chrome=91.0.4472.114)


2021-07-12 10:52:35,194 : getVerificationCode.py : ERROR : Traceback (most recent call last):
  File "/Users/liushiwen/PycharmProjects/MyTestFramwoek/Common/getVerificationCode.py", line 43, in get_code_img_path
    code_location = self.driver.find_element(self.locationType,self.locatorExpression)
  File "/Users/liushiwen/.local/lib/python3.8/site-packages/selenium/webdriver/remote/webdriver.py", line 976, in find_element
    return self.execute(Command.FIND_ELEMENT, {
  File "/Users/liushiwen/.local/lib/python3.8/site-packages/selenium/webdriver/remote/webdriver.py", line 321, in execute
    self.error_handler.check_response(response)
  File "/Users/liushiwen/.local/lib/python3.8/site-packages/selenium/webdriver/remote/errorhandler.py", line 242, in check_response
    raise exception_class(message, screen, stacktrace)
selenium.common.exceptions.NoSuchElementException: Message: no such element: Unable to locate element: {"method":"css selector","selector":"[id="captcha-imgs"]"}
  (Session info: chrome=91.0.4472.114)


2021-07-12 10:54:52,877 : getVerificationCode.py : ERROR : Traceback (most recent call last):
  File "/Users/liushiwen/PycharmProjects/MyTestFramwoek/Common/getVerificationCode.py", line 43, in get_code_img_path
    code_location = self.driver.find_element(self.locationType,self.locatorExpression)
  File "/Users/liushiwen/.local/lib/python3.8/site-packages/selenium/webdriver/remote/webdriver.py", line 976, in find_element
    return self.execute(Command.FIND_ELEMENT, {
  File "/Users/liushiwen/.local/lib/python3.8/site-packages/selenium/webdriver/remote/webdriver.py", line 321, in execute
    self.error_handler.check_response(response)
  File "/Users/liushiwen/.local/lib/python3.8/site-packages/selenium/webdriver/remote/errorhandler.py", line 242, in check_response
    raise exception_class(message, screen, stacktrace)
selenium.common.exceptions.NoSuchElementException: Message: no such element: Unable to locate element: {"method":"xpath","selector":"captcha-img"}
  (Session info: chrome=91.0.4472.114)


2021-07-12 10:56:47,951 : getVerificationCode.py : ERROR : Traceback (most recent call last):
  File "/Users/liushiwen/PycharmProjects/MyTestFramwoek/Common/getVerificationCode.py", line 44, in get_code_img_path
    code_location = self.driver.find_element(self.locationType,self.locatorExpression)
  File "/Users/liushiwen/.local/lib/python3.8/site-packages/selenium/webdriver/remote/webdriver.py", line 976, in find_element
    return self.execute(Command.FIND_ELEMENT, {
  File "/Users/liushiwen/.local/lib/python3.8/site-packages/selenium/webdriver/remote/webdriver.py", line 321, in execute
    self.error_handler.check_response(response)
  File "/Users/liushiwen/.local/lib/python3.8/site-packages/selenium/webdriver/remote/errorhandler.py", line 242, in check_response
    raise exception_class(message, screen, stacktrace)
selenium.common.exceptions.NoSuchElementException: Message: no such element: Unable to locate element: {"method":"css selector","selector":"[id="captcha-imgs"]"}
  (Session info: chrome=91.0.4472.114)


2021-07-12 11:07:45,384 : operateMysql.py : ERROR : Traceback (most recent call last):
  File "/Users/liushiwen/PycharmProjects/MyTestFramwoek/Common/operateMysql.py", line 26, in __init__
    self._conn = pymysql.connect(host=self._host, user=self._user, password=self._password,
  File "/Users/liushiwen/miniforge3/envs/py38/lib/python3.8/site-packages/pymysql/connections.py", line 353, in __init__
    self.connect()
  File "/Users/liushiwen/miniforge3/envs/py38/lib/python3.8/site-packages/pymysql/connections.py", line 633, in connect
    self._request_authentication()
  File "/Users/liushiwen/miniforge3/envs/py38/lib/python3.8/site-packages/pymysql/connections.py", line 932, in _request_authentication
    auth_packet = _auth.caching_sha2_password_auth(self, auth_packet)
  File "/Users/liushiwen/miniforge3/envs/py38/lib/python3.8/site-packages/pymysql/_auth.py", line 266, in caching_sha2_password_auth
    pkt = _roundtrip(conn, data)
  File "/Users/liushiwen/miniforge3/envs/py38/lib/python3.8/site-packages/pymysql/_auth.py", line 120, in _roundtrip
    pkt = conn._read_packet()
  File "/Users/liushiwen/miniforge3/envs/py38/lib/python3.8/site-packages/pymysql/connections.py", line 725, in _read_packet
    packet.raise_for_error()
  File "/Users/liushiwen/miniforge3/envs/py38/lib/python3.8/site-packages/pymysql/protocol.py", line 221, in raise_for_error
    err.raise_mysql_exception(self._data)
  File "/Users/liushiwen/miniforge3/envs/py38/lib/python3.8/site-packages/pymysql/err.py", line 143, in raise_mysql_exception
    raise errorclass(errno, errval)
pymysql.err.OperationalError: (1045, "Access denied for user 'root'@'localhost' (using password: YES)")

2021-07-12 11:09:21,668 : operateMysql.py : ERROR : 请检查传入数据库参数是否正确
2021-07-12 11:09:21,669 : operateMysql.py : ERROR : Traceback (most recent call last):
  File "/Users/liushiwen/PycharmProjects/MyTestFramwoek/Common/operateMysql.py", line 26, in __init__
    self._conn = pymysql.connect(host=self._host, user=self._user, password=self._password,
  File "/Users/liushiwen/miniforge3/envs/py38/lib/python3.8/site-packages/pymysql/connections.py", line 353, in __init__
    self.connect()
  File "/Users/liushiwen/miniforge3/envs/py38/lib/python3.8/site-packages/pymysql/connections.py", line 633, in connect
    self._request_authentication()
  File "/Users/liushiwen/miniforge3/envs/py38/lib/python3.8/site-packages/pymysql/connections.py", line 932, in _request_authentication
    auth_packet = _auth.caching_sha2_password_auth(self, auth_packet)
  File "/Users/liushiwen/miniforge3/envs/py38/lib/python3.8/site-packages/pymysql/_auth.py", line 266, in caching_sha2_password_auth
    pkt = _roundtrip(conn, data)
  File "/Users/liushiwen/miniforge3/envs/py38/lib/python3.8/site-packages/pymysql/_auth.py", line 120, in _roundtrip
    pkt = conn._read_packet()
  File "/Users/liushiwen/miniforge3/envs/py38/lib/python3.8/site-packages/pymysql/connections.py", line 725, in _read_packet
    packet.raise_for_error()
  File "/Users/liushiwen/miniforge3/envs/py38/lib/python3.8/site-packages/pymysql/protocol.py", line 221, in raise_for_error
    err.raise_mysql_exception(self._data)
  File "/Users/liushiwen/miniforge3/envs/py38/lib/python3.8/site-packages/pymysql/err.py", line 143, in raise_mysql_exception
    raise errorclass(errno, errval)
pymysql.err.OperationalError: (1045, "Access denied for user 'root'@'localhost' (using password: YES)")

2021-07-12 11:26:44,816 : operateMysql.py : ERROR : SQL错误，请检查SQL格式是否正确
2021-07-12 11:26:44,817 : operateMysql.py : ERROR : Traceback (most recent call last):
  File "/Users/liushiwen/PycharmProjects/MyTestFramwoek/Common/operateMysql.py", line 52, in singleQuerySQL
    cur.execute(sql)
  File "/Users/liushiwen/miniforge3/envs/py38/lib/python3.8/site-packages/pymysql/cursors.py", line 148, in execute
    result = self._query(query)
  File "/Users/liushiwen/miniforge3/envs/py38/lib/python3.8/site-packages/pymysql/cursors.py", line 310, in _query
    conn.query(q)
  File "/Users/liushiwen/miniforge3/envs/py38/lib/python3.8/site-packages/pymysql/connections.py", line 548, in query
    self._affected_rows = self._read_query_result(unbuffered=unbuffered)
  File "/Users/liushiwen/miniforge3/envs/py38/lib/python3.8/site-packages/pymysql/connections.py", line 775, in _read_query_result
    result.read()
  File "/Users/liushiwen/miniforge3/envs/py38/lib/python3.8/site-packages/pymysql/connections.py", line 1156, in read
    first_packet = self.connection._read_packet()
  File "/Users/liushiwen/miniforge3/envs/py38/lib/python3.8/site-packages/pymysql/connections.py", line 725, in _read_packet
    packet.raise_for_error()
  File "/Users/liushiwen/miniforge3/envs/py38/lib/python3.8/site-packages/pymysql/protocol.py", line 221, in raise_for_error
    err.raise_mysql_exception(self._data)
  File "/Users/liushiwen/miniforge3/envs/py38/lib/python3.8/site-packages/pymysql/err.py", line 143, in raise_mysql_exception
    raise errorclass(errno, errval)
pymysql.err.ProgrammingError: (1064, "You have an error in your SQL syntax; check the manual that corresponds to your MySQL server version for the right syntax to use near 'use limit 2' at line 1")

2021-07-13 13:46:28,613 : operateExcel.py : ERROR : 文件路径不存在，请检查路径是否正确
2021-07-13 13:46:28,614 : operateExcel.py : ERROR : NoneType: None

2021-07-13 13:47:04,890 : operateExcel.py : ERROR : 文件路径不存在，请检查路径是否正确
2021-07-13 13:47:04,890 : operateExcel.py : ERROR : <class 'FileNotFoundError'>
2021-07-13 13:47:40,383 : operateExcel.py : ERROR : 文件路径不存在，请检查路径是否正确
2021-07-13 13:48:13,990 : operateExcel.py : ERROR : 请检查传入sheet是否存在
2021-07-15 09:18:18,186 : getLog.py : ERROR : Traceback (most recent call last):
  File "/Users/liushiwen/PycharmProjects/MyTestFramwoek/Common/getLog.py", line 82, in func
    num_sum = num1 * num2
TypeError: can't multiply sequence by non-int of type 'str'

2021-07-15 10:52:30,657 : sendEmail.py : ERROR : Traceback (most recent call last):
  File "/Users/liushiwen/PycharmProjects/MyTestFramwoek/Common/sendEmail.py", line 53, in mail_message
    with open(file=self.content_html_file, mode="r", encoding="utf-8") as file:
FileNotFoundError: [Errno 2] No such file or directory: '2020-05-20-23_11_43_result.html'

2021-07-15 10:52:30,657 : sendEmail.py : ERROR : Traceback (most recent call last):
  File "/Users/liushiwen/PycharmProjects/MyTestFramwoek/Common/sendEmail.py", line 62, in mail_message
    'content_html': self.content_html,
AttributeError: 'SendEmail' object has no attribute 'content_html'

2021-07-15 10:52:30,658 : sendEmail.py : ERROR : Traceback (most recent call last):
  File "/Users/liushiwen/PycharmProjects/MyTestFramwoek/Common/sendEmail.py", line 92, in send_email
    self.server.send_mail(recipients=recipients_info,cc=carbon_copy_info,mail=self.msg)
  File "/Users/liushiwen/.local/lib/python3.8/site-packages/zmail/server.py", line 96, in send_mail
    _mail = Mail(mail, debug=self.debug, log=self.log)
  File "/Users/liushiwen/.local/lib/python3.8/site-packages/zmail/mime.py", line 27, in __init__
    raise InvalidArguments('mail field excepted type dict or CaseInsensitiveDict got {}'.format(type(mail)))
zmail.exceptions.InvalidArguments: mail field excepted type dict or CaseInsensitiveDict got <class 'NoneType'>

2021-07-15 15:04:03,537 : browser.py : ERROR : 仅支持firefox, chrome, ie, phantomjs!
2021-07-15 15:04:03,537 : browser.py : ERROR : NoneType: None

2021-07-15 15:04:33,271 : browser.py : ERROR : NoneType: None

2021-07-15 15:04:47,179 : browser.py : ERROR : 仅支持firefox, chrome, ie, phantomjs!
2021-07-15 15:07:54,116 : browser.py : ERROR : 请检查url是否传入
2021-07-15 15:07:54,128 : browser.py : ERROR : Traceback (most recent call last):
  File "/Users/liushiwen/PycharmProjects/MyTestFramwoek/Common/browser.py", line 35, in get
    self.driver.get(url)
  File "/Users/liushiwen/.local/lib/python3.8/site-packages/selenium/webdriver/remote/webdriver.py", line 333, in get
    self.execute(Command.GET, {'url': url})
  File "/Users/liushiwen/.local/lib/python3.8/site-packages/selenium/webdriver/remote/webdriver.py", line 321, in execute
    self.error_handler.check_response(response)
  File "/Users/liushiwen/.local/lib/python3.8/site-packages/selenium/webdriver/remote/errorhandler.py", line 242, in check_response
    raise exception_class(message, screen, stacktrace)
selenium.common.exceptions.InvalidArgumentException: Message: invalid argument: 'url' must be a string
  (Session info: chrome=91.0.4472.114)


2021-07-15 15:27:57,701 : client.py : ERROR : 不支持的method:HAHA，请检查传入参数！
2021-07-16 11:02:09,966 : APIMethodEntrance.py : ERROR : Traceback (most recent call last):
  File "/Users/liushiwen/PycharmProjects/MyTestFramwoek/KernelEntrace/APIMethodEntrance.py", line 13, in func
    num_sum = num1 * num2
TypeError: can't multiply sequence by non-int of type 'str'

2021-07-21 09:26:31,871 : basepage.py : ERROR : 请检查url格式是否正确
2021-07-21 09:26:31,874 : basepage.py : ERROR : Traceback (most recent call last):
  File "/Users/liushiwen/PycharmProjects/MyTestFramwoek/UITestObjects/BaseFactory/basepage.py", line 91, in get
    self.driver.get(url)
  File "/Users/liushiwen/.local/lib/python3.8/site-packages/selenium/webdriver/remote/webdriver.py", line 333, in get
    self.execute(Command.GET, {'url': url})
  File "/Users/liushiwen/.local/lib/python3.8/site-packages/selenium/webdriver/remote/webdriver.py", line 321, in execute
    self.error_handler.check_response(response)
  File "/Users/liushiwen/.local/lib/python3.8/site-packages/selenium/webdriver/remote/errorhandler.py", line 242, in check_response
    raise exception_class(message, screen, stacktrace)
selenium.common.exceptions.WebDriverException: Message: chrome not reachable
  (Session info: chrome=91.0.4472.164)


2021-07-21 09:26:31,877 : basepage.py : ERROR : 请检查定位方式和定位表达式格式是否正确
2021-07-21 09:26:31,877 : basepage.py : ERROR : 请检查定位方式和定位表达式格式是否正确
2021-07-21 09:26:31,877 : basepage.py : ERROR : Traceback (most recent call last):
  File "/Users/liushiwen/PycharmProjects/MyTestFramwoek/UITestObjects/BaseFactory/basepage.py", line 124, in find_element
    return self.driver.find_element(self.locationTypeDict[location_type.lower()], locator_expression)
  File "/Users/liushiwen/.local/lib/python3.8/site-packages/selenium/webdriver/remote/webdriver.py", line 976, in find_element
    return self.execute(Command.FIND_ELEMENT, {
  File "/Users/liushiwen/.local/lib/python3.8/site-packages/selenium/webdriver/remote/webdriver.py", line 321, in execute
    self.error_handler.check_response(response)
  File "/Users/liushiwen/.local/lib/python3.8/site-packages/selenium/webdriver/remote/errorhandler.py", line 242, in check_response
    raise exception_class(message, screen, stacktrace)
selenium.common.exceptions.WebDriverException: Message: chrome not reachable
  (Session info: chrome=91.0.4472.164)


2021-07-21 09:26:31,877 : basepage.py : ERROR : Traceback (most recent call last):
  File "/Users/liushiwen/PycharmProjects/MyTestFramwoek/UITestObjects/BaseFactory/basepage.py", line 124, in find_element
    return self.driver.find_element(self.locationTypeDict[location_type.lower()], locator_expression)
  File "/Users/liushiwen/.local/lib/python3.8/site-packages/selenium/webdriver/remote/webdriver.py", line 976, in find_element
    return self.execute(Command.FIND_ELEMENT, {
  File "/Users/liushiwen/.local/lib/python3.8/site-packages/selenium/webdriver/remote/webdriver.py", line 321, in execute
    self.error_handler.check_response(response)
  File "/Users/liushiwen/.local/lib/python3.8/site-packages/selenium/webdriver/remote/errorhandler.py", line 242, in check_response
    raise exception_class(message, screen, stacktrace)
selenium.common.exceptions.WebDriverException: Message: chrome not reachable
  (Session info: chrome=91.0.4472.164)


2021-07-21 09:26:32,381 : basepage.py : ERROR : 请检查定位方式和定位表达式格式是否正确
2021-07-21 09:26:32,381 : basepage.py : ERROR : 请检查定位方式和定位表达式格式是否正确
2021-07-21 09:26:32,381 : basepage.py : ERROR : Traceback (most recent call last):
  File "/Users/liushiwen/PycharmProjects/MyTestFramwoek/UITestObjects/BaseFactory/basepage.py", line 124, in find_element
    return self.driver.find_element(self.locationTypeDict[location_type.lower()], locator_expression)
  File "/Users/liushiwen/.local/lib/python3.8/site-packages/selenium/webdriver/remote/webdriver.py", line 976, in find_element
    return self.execute(Command.FIND_ELEMENT, {
  File "/Users/liushiwen/.local/lib/python3.8/site-packages/selenium/webdriver/remote/webdriver.py", line 321, in execute
    self.error_handler.check_response(response)
  File "/Users/liushiwen/.local/lib/python3.8/site-packages/selenium/webdriver/remote/errorhandler.py", line 242, in check_response
    raise exception_class(message, screen, stacktrace)
selenium.common.exceptions.WebDriverException: Message: chrome not reachable
  (Session info: chrome=91.0.4472.164)


2021-07-21 09:26:32,381 : basepage.py : ERROR : Traceback (most recent call last):
  File "/Users/liushiwen/PycharmProjects/MyTestFramwoek/UITestObjects/BaseFactory/basepage.py", line 124, in find_element
    return self.driver.find_element(self.locationTypeDict[location_type.lower()], locator_expression)
  File "/Users/liushiwen/.local/lib/python3.8/site-packages/selenium/webdriver/remote/webdriver.py", line 976, in find_element
    return self.execute(Command.FIND_ELEMENT, {
  File "/Users/liushiwen/.local/lib/python3.8/site-packages/selenium/webdriver/remote/webdriver.py", line 321, in execute
    self.error_handler.check_response(response)
  File "/Users/liushiwen/.local/lib/python3.8/site-packages/selenium/webdriver/remote/errorhandler.py", line 242, in check_response
    raise exception_class(message, screen, stacktrace)
selenium.common.exceptions.WebDriverException: Message: chrome not reachable
  (Session info: chrome=91.0.4472.164)


2021-07-21 09:26:32,889 : basepage.py : ERROR : 请检查定位方式和定位表达式格式是否正确
2021-07-21 09:26:32,889 : basepage.py : ERROR : 请检查定位方式和定位表达式格式是否正确
2021-07-21 09:26:32,889 : basepage.py : ERROR : Traceback (most recent call last):
  File "/Users/liushiwen/PycharmProjects/MyTestFramwoek/UITestObjects/BaseFactory/basepage.py", line 124, in find_element
    return self.driver.find_element(self.locationTypeDict[location_type.lower()], locator_expression)
  File "/Users/liushiwen/.local/lib/python3.8/site-packages/selenium/webdriver/remote/webdriver.py", line 976, in find_element
    return self.execute(Command.FIND_ELEMENT, {
  File "/Users/liushiwen/.local/lib/python3.8/site-packages/selenium/webdriver/remote/webdriver.py", line 321, in execute
    self.error_handler.check_response(response)
  File "/Users/liushiwen/.local/lib/python3.8/site-packages/selenium/webdriver/remote/errorhandler.py", line 242, in check_response
    raise exception_class(message, screen, stacktrace)
selenium.common.exceptions.WebDriverException: Message: chrome not reachable
  (Session info: chrome=91.0.4472.164)


2021-07-21 09:26:32,889 : basepage.py : ERROR : Traceback (most recent call last):
  File "/Users/liushiwen/PycharmProjects/MyTestFramwoek/UITestObjects/BaseFactory/basepage.py", line 124, in find_element
    return self.driver.find_element(self.locationTypeDict[location_type.lower()], locator_expression)
  File "/Users/liushiwen/.local/lib/python3.8/site-packages/selenium/webdriver/remote/webdriver.py", line 976, in find_element
    return self.execute(Command.FIND_ELEMENT, {
  File "/Users/liushiwen/.local/lib/python3.8/site-packages/selenium/webdriver/remote/webdriver.py", line 321, in execute
    self.error_handler.check_response(response)
  File "/Users/liushiwen/.local/lib/python3.8/site-packages/selenium/webdriver/remote/errorhandler.py", line 242, in check_response
    raise exception_class(message, screen, stacktrace)
selenium.common.exceptions.WebDriverException: Message: chrome not reachable
  (Session info: chrome=91.0.4472.164)


2021-07-21 09:26:33,403 : basepage.py : ERROR : 请检查定位方式和定位表达式格式是否正确
2021-07-21 09:26:33,403 : basepage.py : ERROR : 请检查定位方式和定位表达式格式是否正确
2021-07-21 09:26:33,404 : basepage.py : ERROR : Traceback (most recent call last):
  File "/Users/liushiwen/PycharmProjects/MyTestFramwoek/UITestObjects/BaseFactory/basepage.py", line 124, in find_element
    return self.driver.find_element(self.locationTypeDict[location_type.lower()], locator_expression)
  File "/Users/liushiwen/.local/lib/python3.8/site-packages/selenium/webdriver/remote/webdriver.py", line 976, in find_element
    return self.execute(Command.FIND_ELEMENT, {
  File "/Users/liushiwen/.local/lib/python3.8/site-packages/selenium/webdriver/remote/webdriver.py", line 321, in execute
    self.error_handler.check_response(response)
  File "/Users/liushiwen/.local/lib/python3.8/site-packages/selenium/webdriver/remote/errorhandler.py", line 242, in check_response
    raise exception_class(message, screen, stacktrace)
selenium.common.exceptions.WebDriverException: Message: chrome not reachable
  (Session info: chrome=91.0.4472.164)


2021-07-21 09:26:33,404 : basepage.py : ERROR : Traceback (most recent call last):
  File "/Users/liushiwen/PycharmProjects/MyTestFramwoek/UITestObjects/BaseFactory/basepage.py", line 124, in find_element
    return self.driver.find_element(self.locationTypeDict[location_type.lower()], locator_expression)
  File "/Users/liushiwen/.local/lib/python3.8/site-packages/selenium/webdriver/remote/webdriver.py", line 976, in find_element
    return self.execute(Command.FIND_ELEMENT, {
  File "/Users/liushiwen/.local/lib/python3.8/site-packages/selenium/webdriver/remote/webdriver.py", line 321, in execute
    self.error_handler.check_response(response)
  File "/Users/liushiwen/.local/lib/python3.8/site-packages/selenium/webdriver/remote/errorhandler.py", line 242, in check_response
    raise exception_class(message, screen, stacktrace)
selenium.common.exceptions.WebDriverException: Message: chrome not reachable
  (Session info: chrome=91.0.4472.164)


2021-07-21 09:26:33,909 : basepage.py : ERROR : 请检查定位方式和定位表达式格式是否正确
2021-07-21 09:26:33,909 : basepage.py : ERROR : 请检查定位方式和定位表达式格式是否正确
2021-07-21 09:26:33,910 : basepage.py : ERROR : Traceback (most recent call last):
  File "/Users/liushiwen/PycharmProjects/MyTestFramwoek/UITestObjects/BaseFactory/basepage.py", line 124, in find_element
    return self.driver.find_element(self.locationTypeDict[location_type.lower()], locator_expression)
  File "/Users/liushiwen/.local/lib/python3.8/site-packages/selenium/webdriver/remote/webdriver.py", line 976, in find_element
    return self.execute(Command.FIND_ELEMENT, {
  File "/Users/liushiwen/.local/lib/python3.8/site-packages/selenium/webdriver/remote/webdriver.py", line 321, in execute
    self.error_handler.check_response(response)
  File "/Users/liushiwen/.local/lib/python3.8/site-packages/selenium/webdriver/remote/errorhandler.py", line 242, in check_response
    raise exception_class(message, screen, stacktrace)
selenium.common.exceptions.WebDriverException: Message: chrome not reachable
  (Session info: chrome=91.0.4472.164)


2021-07-21 09:26:33,910 : basepage.py : ERROR : Traceback (most recent call last):
  File "/Users/liushiwen/PycharmProjects/MyTestFramwoek/UITestObjects/BaseFactory/basepage.py", line 124, in find_element
    return self.driver.find_element(self.locationTypeDict[location_type.lower()], locator_expression)
  File "/Users/liushiwen/.local/lib/python3.8/site-packages/selenium/webdriver/remote/webdriver.py", line 976, in find_element
    return self.execute(Command.FIND_ELEMENT, {
  File "/Users/liushiwen/.local/lib/python3.8/site-packages/selenium/webdriver/remote/webdriver.py", line 321, in execute
    self.error_handler.check_response(response)
  File "/Users/liushiwen/.local/lib/python3.8/site-packages/selenium/webdriver/remote/errorhandler.py", line 242, in check_response
    raise exception_class(message, screen, stacktrace)
selenium.common.exceptions.WebDriverException: Message: chrome not reachable
  (Session info: chrome=91.0.4472.164)


2021-07-21 09:26:34,418 : basepage.py : ERROR : 请检查定位方式和定位表达式格式是否正确
2021-07-21 09:26:34,418 : basepage.py : ERROR : 请检查定位方式和定位表达式格式是否正确
2021-07-21 09:26:34,418 : basepage.py : ERROR : Traceback (most recent call last):
  File "/Users/liushiwen/PycharmProjects/MyTestFramwoek/UITestObjects/BaseFactory/basepage.py", line 124, in find_element
    return self.driver.find_element(self.locationTypeDict[location_type.lower()], locator_expression)
  File "/Users/liushiwen/.local/lib/python3.8/site-packages/selenium/webdriver/remote/webdriver.py", line 976, in find_element
    return self.execute(Command.FIND_ELEMENT, {
  File "/Users/liushiwen/.local/lib/python3.8/site-packages/selenium/webdriver/remote/webdriver.py", line 321, in execute
    self.error_handler.check_response(response)
  File "/Users/liushiwen/.local/lib/python3.8/site-packages/selenium/webdriver/remote/errorhandler.py", line 242, in check_response
    raise exception_class(message, screen, stacktrace)
selenium.common.exceptions.WebDriverException: Message: chrome not reachable
  (Session info: chrome=91.0.4472.164)


2021-07-21 09:26:34,418 : basepage.py : ERROR : Traceback (most recent call last):
  File "/Users/liushiwen/PycharmProjects/MyTestFramwoek/UITestObjects/BaseFactory/basepage.py", line 124, in find_element
    return self.driver.find_element(self.locationTypeDict[location_type.lower()], locator_expression)
  File "/Users/liushiwen/.local/lib/python3.8/site-packages/selenium/webdriver/remote/webdriver.py", line 976, in find_element
    return self.execute(Command.FIND_ELEMENT, {
  File "/Users/liushiwen/.local/lib/python3.8/site-packages/selenium/webdriver/remote/webdriver.py", line 321, in execute
    self.error_handler.check_response(response)
  File "/Users/liushiwen/.local/lib/python3.8/site-packages/selenium/webdriver/remote/errorhandler.py", line 242, in check_response
    raise exception_class(message, screen, stacktrace)
selenium.common.exceptions.WebDriverException: Message: chrome not reachable
  (Session info: chrome=91.0.4472.164)


2021-07-21 09:26:34,925 : basepage.py : ERROR : 请检查定位方式和定位表达式格式是否正确
2021-07-21 09:26:34,925 : basepage.py : ERROR : 请检查定位方式和定位表达式格式是否正确
2021-07-21 09:26:34,926 : basepage.py : ERROR : Traceback (most recent call last):
  File "/Users/liushiwen/PycharmProjects/MyTestFramwoek/UITestObjects/BaseFactory/basepage.py", line 124, in find_element
    return self.driver.find_element(self.locationTypeDict[location_type.lower()], locator_expression)
  File "/Users/liushiwen/.local/lib/python3.8/site-packages/selenium/webdriver/remote/webdriver.py", line 976, in find_element
    return self.execute(Command.FIND_ELEMENT, {
  File "/Users/liushiwen/.local/lib/python3.8/site-packages/selenium/webdriver/remote/webdriver.py", line 321, in execute
    self.error_handler.check_response(response)
  File "/Users/liushiwen/.local/lib/python3.8/site-packages/selenium/webdriver/remote/errorhandler.py", line 242, in check_response
    raise exception_class(message, screen, stacktrace)
selenium.common.exceptions.WebDriverException: Message: chrome not reachable
  (Session info: chrome=91.0.4472.164)


2021-07-21 09:26:34,926 : basepage.py : ERROR : Traceback (most recent call last):
  File "/Users/liushiwen/PycharmProjects/MyTestFramwoek/UITestObjects/BaseFactory/basepage.py", line 124, in find_element
    return self.driver.find_element(self.locationTypeDict[location_type.lower()], locator_expression)
  File "/Users/liushiwen/.local/lib/python3.8/site-packages/selenium/webdriver/remote/webdriver.py", line 976, in find_element
    return self.execute(Command.FIND_ELEMENT, {
  File "/Users/liushiwen/.local/lib/python3.8/site-packages/selenium/webdriver/remote/webdriver.py", line 321, in execute
    self.error_handler.check_response(response)
  File "/Users/liushiwen/.local/lib/python3.8/site-packages/selenium/webdriver/remote/errorhandler.py", line 242, in check_response
    raise exception_class(message, screen, stacktrace)
selenium.common.exceptions.WebDriverException: Message: chrome not reachable
  (Session info: chrome=91.0.4472.164)


2021-07-21 09:26:35,434 : basepage.py : ERROR : 请检查定位方式和定位表达式格式是否正确
2021-07-21 09:26:35,434 : basepage.py : ERROR : 请检查定位方式和定位表达式格式是否正确
2021-07-21 09:26:35,435 : basepage.py : ERROR : Traceback (most recent call last):
  File "/Users/liushiwen/PycharmProjects/MyTestFramwoek/UITestObjects/BaseFactory/basepage.py", line 124, in find_element
    return self.driver.find_element(self.locationTypeDict[location_type.lower()], locator_expression)
  File "/Users/liushiwen/.local/lib/python3.8/site-packages/selenium/webdriver/remote/webdriver.py", line 976, in find_element
    return self.execute(Command.FIND_ELEMENT, {
  File "/Users/liushiwen/.local/lib/python3.8/site-packages/selenium/webdriver/remote/webdriver.py", line 321, in execute
    self.error_handler.check_response(response)
  File "/Users/liushiwen/.local/lib/python3.8/site-packages/selenium/webdriver/remote/errorhandler.py", line 242, in check_response
    raise exception_class(message, screen, stacktrace)
selenium.common.exceptions.WebDriverException: Message: chrome not reachable
  (Session info: chrome=91.0.4472.164)


2021-07-21 09:26:35,435 : basepage.py : ERROR : Traceback (most recent call last):
  File "/Users/liushiwen/PycharmProjects/MyTestFramwoek/UITestObjects/BaseFactory/basepage.py", line 124, in find_element
    return self.driver.find_element(self.locationTypeDict[location_type.lower()], locator_expression)
  File "/Users/liushiwen/.local/lib/python3.8/site-packages/selenium/webdriver/remote/webdriver.py", line 976, in find_element
    return self.execute(Command.FIND_ELEMENT, {
  File "/Users/liushiwen/.local/lib/python3.8/site-packages/selenium/webdriver/remote/webdriver.py", line 321, in execute
    self.error_handler.check_response(response)
  File "/Users/liushiwen/.local/lib/python3.8/site-packages/selenium/webdriver/remote/errorhandler.py", line 242, in check_response
    raise exception_class(message, screen, stacktrace)
selenium.common.exceptions.WebDriverException: Message: chrome not reachable
  (Session info: chrome=91.0.4472.164)


2021-07-21 09:26:35,944 : basepage.py : ERROR : 请检查定位方式和定位表达式格式是否正确
2021-07-21 09:26:35,944 : basepage.py : ERROR : 请检查定位方式和定位表达式格式是否正确
2021-07-21 09:26:35,945 : basepage.py : ERROR : Traceback (most recent call last):
  File "/Users/liushiwen/PycharmProjects/MyTestFramwoek/UITestObjects/BaseFactory/basepage.py", line 124, in find_element
    return self.driver.find_element(self.locationTypeDict[location_type.lower()], locator_expression)
  File "/Users/liushiwen/.local/lib/python3.8/site-packages/selenium/webdriver/remote/webdriver.py", line 976, in find_element
    return self.execute(Command.FIND_ELEMENT, {
  File "/Users/liushiwen/.local/lib/python3.8/site-packages/selenium/webdriver/remote/webdriver.py", line 321, in execute
    self.error_handler.check_response(response)
  File "/Users/liushiwen/.local/lib/python3.8/site-packages/selenium/webdriver/remote/errorhandler.py", line 242, in check_response
    raise exception_class(message, screen, stacktrace)
selenium.common.exceptions.WebDriverException: Message: chrome not reachable
  (Session info: chrome=91.0.4472.164)


2021-07-21 09:26:35,945 : basepage.py : ERROR : Traceback (most recent call last):
  File "/Users/liushiwen/PycharmProjects/MyTestFramwoek/UITestObjects/BaseFactory/basepage.py", line 124, in find_element
    return self.driver.find_element(self.locationTypeDict[location_type.lower()], locator_expression)
  File "/Users/liushiwen/.local/lib/python3.8/site-packages/selenium/webdriver/remote/webdriver.py", line 976, in find_element
    return self.execute(Command.FIND_ELEMENT, {
  File "/Users/liushiwen/.local/lib/python3.8/site-packages/selenium/webdriver/remote/webdriver.py", line 321, in execute
    self.error_handler.check_response(response)
  File "/Users/liushiwen/.local/lib/python3.8/site-packages/selenium/webdriver/remote/errorhandler.py", line 242, in check_response
    raise exception_class(message, screen, stacktrace)
selenium.common.exceptions.WebDriverException: Message: chrome not reachable
  (Session info: chrome=91.0.4472.164)


2021-07-21 09:26:36,453 : basepage.py : ERROR : 请检查定位方式和定位表达式格式是否正确
2021-07-21 09:26:36,453 : basepage.py : ERROR : 请检查定位方式和定位表达式格式是否正确
2021-07-21 09:26:36,454 : basepage.py : ERROR : Traceback (most recent call last):
  File "/Users/liushiwen/PycharmProjects/MyTestFramwoek/UITestObjects/BaseFactory/basepage.py", line 124, in find_element
    return self.driver.find_element(self.locationTypeDict[location_type.lower()], locator_expression)
  File "/Users/liushiwen/.local/lib/python3.8/site-packages/selenium/webdriver/remote/webdriver.py", line 976, in find_element
    return self.execute(Command.FIND_ELEMENT, {
  File "/Users/liushiwen/.local/lib/python3.8/site-packages/selenium/webdriver/remote/webdriver.py", line 321, in execute
    self.error_handler.check_response(response)
  File "/Users/liushiwen/.local/lib/python3.8/site-packages/selenium/webdriver/remote/errorhandler.py", line 242, in check_response
    raise exception_class(message, screen, stacktrace)
selenium.common.exceptions.WebDriverException: Message: chrome not reachable
  (Session info: chrome=91.0.4472.164)


2021-07-21 09:26:36,454 : basepage.py : ERROR : Traceback (most recent call last):
  File "/Users/liushiwen/PycharmProjects/MyTestFramwoek/UITestObjects/BaseFactory/basepage.py", line 124, in find_element
    return self.driver.find_element(self.locationTypeDict[location_type.lower()], locator_expression)
  File "/Users/liushiwen/.local/lib/python3.8/site-packages/selenium/webdriver/remote/webdriver.py", line 976, in find_element
    return self.execute(Command.FIND_ELEMENT, {
  File "/Users/liushiwen/.local/lib/python3.8/site-packages/selenium/webdriver/remote/webdriver.py", line 321, in execute
    self.error_handler.check_response(response)
  File "/Users/liushiwen/.local/lib/python3.8/site-packages/selenium/webdriver/remote/errorhandler.py", line 242, in check_response
    raise exception_class(message, screen, stacktrace)
selenium.common.exceptions.WebDriverException: Message: chrome not reachable
  (Session info: chrome=91.0.4472.164)


2021-07-21 09:26:36,971 : basepage.py : ERROR : 请检查定位方式和定位表达式格式是否正确
2021-07-21 09:26:36,971 : basepage.py : ERROR : 请检查定位方式和定位表达式格式是否正确
2021-07-21 09:26:36,973 : basepage.py : ERROR : Traceback (most recent call last):
  File "/Users/liushiwen/PycharmProjects/MyTestFramwoek/UITestObjects/BaseFactory/basepage.py", line 124, in find_element
    return self.driver.find_element(self.locationTypeDict[location_type.lower()], locator_expression)
  File "/Users/liushiwen/.local/lib/python3.8/site-packages/selenium/webdriver/remote/webdriver.py", line 976, in find_element
    return self.execute(Command.FIND_ELEMENT, {
  File "/Users/liushiwen/.local/lib/python3.8/site-packages/selenium/webdriver/remote/webdriver.py", line 321, in execute
    self.error_handler.check_response(response)
  File "/Users/liushiwen/.local/lib/python3.8/site-packages/selenium/webdriver/remote/errorhandler.py", line 242, in check_response
    raise exception_class(message, screen, stacktrace)
selenium.common.exceptions.WebDriverException: Message: chrome not reachable
  (Session info: chrome=91.0.4472.164)


2021-07-21 09:26:36,973 : basepage.py : ERROR : Traceback (most recent call last):
  File "/Users/liushiwen/PycharmProjects/MyTestFramwoek/UITestObjects/BaseFactory/basepage.py", line 124, in find_element
    return self.driver.find_element(self.locationTypeDict[location_type.lower()], locator_expression)
  File "/Users/liushiwen/.local/lib/python3.8/site-packages/selenium/webdriver/remote/webdriver.py", line 976, in find_element
    return self.execute(Command.FIND_ELEMENT, {
  File "/Users/liushiwen/.local/lib/python3.8/site-packages/selenium/webdriver/remote/webdriver.py", line 321, in execute
    self.error_handler.check_response(response)
  File "/Users/liushiwen/.local/lib/python3.8/site-packages/selenium/webdriver/remote/errorhandler.py", line 242, in check_response
    raise exception_class(message, screen, stacktrace)
selenium.common.exceptions.WebDriverException: Message: chrome not reachable
  (Session info: chrome=91.0.4472.164)


2021-07-21 09:26:37,487 : basepage.py : ERROR : 请检查定位方式和定位表达式格式是否正确
2021-07-21 09:26:37,487 : basepage.py : ERROR : 请检查定位方式和定位表达式格式是否正确
2021-07-21 09:26:37,487 : basepage.py : ERROR : Traceback (most recent call last):
  File "/Users/liushiwen/PycharmProjects/MyTestFramwoek/UITestObjects/BaseFactory/basepage.py", line 124, in find_element
    return self.driver.find_element(self.locationTypeDict[location_type.lower()], locator_expression)
  File "/Users/liushiwen/.local/lib/python3.8/site-packages/selenium/webdriver/remote/webdriver.py", line 976, in find_element
    return self.execute(Command.FIND_ELEMENT, {
  File "/Users/liushiwen/.local/lib/python3.8/site-packages/selenium/webdriver/remote/webdriver.py", line 321, in execute
    self.error_handler.check_response(response)
  File "/Users/liushiwen/.local/lib/python3.8/site-packages/selenium/webdriver/remote/errorhandler.py", line 242, in check_response
    raise exception_class(message, screen, stacktrace)
selenium.common.exceptions.WebDriverException: Message: chrome not reachable
  (Session info: chrome=91.0.4472.164)


2021-07-21 09:26:37,487 : basepage.py : ERROR : Traceback (most recent call last):
  File "/Users/liushiwen/PycharmProjects/MyTestFramwoek/UITestObjects/BaseFactory/basepage.py", line 124, in find_element
    return self.driver.find_element(self.locationTypeDict[location_type.lower()], locator_expression)
  File "/Users/liushiwen/.local/lib/python3.8/site-packages/selenium/webdriver/remote/webdriver.py", line 976, in find_element
    return self.execute(Command.FIND_ELEMENT, {
  File "/Users/liushiwen/.local/lib/python3.8/site-packages/selenium/webdriver/remote/webdriver.py", line 321, in execute
    self.error_handler.check_response(response)
  File "/Users/liushiwen/.local/lib/python3.8/site-packages/selenium/webdriver/remote/errorhandler.py", line 242, in check_response
    raise exception_class(message, screen, stacktrace)
selenium.common.exceptions.WebDriverException: Message: chrome not reachable
  (Session info: chrome=91.0.4472.164)


2021-07-21 09:26:37,995 : basepage.py : ERROR : 请检查定位方式和定位表达式格式是否正确
2021-07-21 09:26:37,995 : basepage.py : ERROR : 请检查定位方式和定位表达式格式是否正确
2021-07-21 09:26:37,995 : basepage.py : ERROR : Traceback (most recent call last):
  File "/Users/liushiwen/PycharmProjects/MyTestFramwoek/UITestObjects/BaseFactory/basepage.py", line 124, in find_element
    return self.driver.find_element(self.locationTypeDict[location_type.lower()], locator_expression)
  File "/Users/liushiwen/.local/lib/python3.8/site-packages/selenium/webdriver/remote/webdriver.py", line 976, in find_element
    return self.execute(Command.FIND_ELEMENT, {
  File "/Users/liushiwen/.local/lib/python3.8/site-packages/selenium/webdriver/remote/webdriver.py", line 321, in execute
    self.error_handler.check_response(response)
  File "/Users/liushiwen/.local/lib/python3.8/site-packages/selenium/webdriver/remote/errorhandler.py", line 242, in check_response
    raise exception_class(message, screen, stacktrace)
selenium.common.exceptions.WebDriverException: Message: chrome not reachable
  (Session info: chrome=91.0.4472.164)


2021-07-21 09:26:37,995 : basepage.py : ERROR : Traceback (most recent call last):
  File "/Users/liushiwen/PycharmProjects/MyTestFramwoek/UITestObjects/BaseFactory/basepage.py", line 124, in find_element
    return self.driver.find_element(self.locationTypeDict[location_type.lower()], locator_expression)
  File "/Users/liushiwen/.local/lib/python3.8/site-packages/selenium/webdriver/remote/webdriver.py", line 976, in find_element
    return self.execute(Command.FIND_ELEMENT, {
  File "/Users/liushiwen/.local/lib/python3.8/site-packages/selenium/webdriver/remote/webdriver.py", line 321, in execute
    self.error_handler.check_response(response)
  File "/Users/liushiwen/.local/lib/python3.8/site-packages/selenium/webdriver/remote/errorhandler.py", line 242, in check_response
    raise exception_class(message, screen, stacktrace)
selenium.common.exceptions.WebDriverException: Message: chrome not reachable
  (Session info: chrome=91.0.4472.164)


2021-07-21 09:26:38,508 : basepage.py : ERROR : 请检查定位方式和定位表达式格式是否正确
2021-07-21 09:26:38,508 : basepage.py : ERROR : 请检查定位方式和定位表达式格式是否正确
2021-07-21 09:26:38,509 : basepage.py : ERROR : Traceback (most recent call last):
  File "/Users/liushiwen/PycharmProjects/MyTestFramwoek/UITestObjects/BaseFactory/basepage.py", line 124, in find_element
    return self.driver.find_element(self.locationTypeDict[location_type.lower()], locator_expression)
  File "/Users/liushiwen/.local/lib/python3.8/site-packages/selenium/webdriver/remote/webdriver.py", line 976, in find_element
    return self.execute(Command.FIND_ELEMENT, {
  File "/Users/liushiwen/.local/lib/python3.8/site-packages/selenium/webdriver/remote/webdriver.py", line 321, in execute
    self.error_handler.check_response(response)
  File "/Users/liushiwen/.local/lib/python3.8/site-packages/selenium/webdriver/remote/errorhandler.py", line 242, in check_response
    raise exception_class(message, screen, stacktrace)
selenium.common.exceptions.WebDriverException: Message: chrome not reachable
  (Session info: chrome=91.0.4472.164)


2021-07-21 09:26:38,509 : basepage.py : ERROR : Traceback (most recent call last):
  File "/Users/liushiwen/PycharmProjects/MyTestFramwoek/UITestObjects/BaseFactory/basepage.py", line 124, in find_element
    return self.driver.find_element(self.locationTypeDict[location_type.lower()], locator_expression)
  File "/Users/liushiwen/.local/lib/python3.8/site-packages/selenium/webdriver/remote/webdriver.py", line 976, in find_element
    return self.execute(Command.FIND_ELEMENT, {
  File "/Users/liushiwen/.local/lib/python3.8/site-packages/selenium/webdriver/remote/webdriver.py", line 321, in execute
    self.error_handler.check_response(response)
  File "/Users/liushiwen/.local/lib/python3.8/site-packages/selenium/webdriver/remote/errorhandler.py", line 242, in check_response
    raise exception_class(message, screen, stacktrace)
selenium.common.exceptions.WebDriverException: Message: chrome not reachable
  (Session info: chrome=91.0.4472.164)


2021-07-21 09:26:39,016 : basepage.py : ERROR : 请检查定位方式和定位表达式格式是否正确
2021-07-21 09:26:39,016 : basepage.py : ERROR : 请检查定位方式和定位表达式格式是否正确
2021-07-21 09:26:39,016 : basepage.py : ERROR : Traceback (most recent call last):
  File "/Users/liushiwen/PycharmProjects/MyTestFramwoek/UITestObjects/BaseFactory/basepage.py", line 124, in find_element
    return self.driver.find_element(self.locationTypeDict[location_type.lower()], locator_expression)
  File "/Users/liushiwen/.local/lib/python3.8/site-packages/selenium/webdriver/remote/webdriver.py", line 976, in find_element
    return self.execute(Command.FIND_ELEMENT, {
  File "/Users/liushiwen/.local/lib/python3.8/site-packages/selenium/webdriver/remote/webdriver.py", line 321, in execute
    self.error_handler.check_response(response)
  File "/Users/liushiwen/.local/lib/python3.8/site-packages/selenium/webdriver/remote/errorhandler.py", line 242, in check_response
    raise exception_class(message, screen, stacktrace)
selenium.common.exceptions.WebDriverException: Message: chrome not reachable
  (Session info: chrome=91.0.4472.164)


2021-07-21 09:26:39,016 : basepage.py : ERROR : Traceback (most recent call last):
  File "/Users/liushiwen/PycharmProjects/MyTestFramwoek/UITestObjects/BaseFactory/basepage.py", line 124, in find_element
    return self.driver.find_element(self.locationTypeDict[location_type.lower()], locator_expression)
  File "/Users/liushiwen/.local/lib/python3.8/site-packages/selenium/webdriver/remote/webdriver.py", line 976, in find_element
    return self.execute(Command.FIND_ELEMENT, {
  File "/Users/liushiwen/.local/lib/python3.8/site-packages/selenium/webdriver/remote/webdriver.py", line 321, in execute
    self.error_handler.check_response(response)
  File "/Users/liushiwen/.local/lib/python3.8/site-packages/selenium/webdriver/remote/errorhandler.py", line 242, in check_response
    raise exception_class(message, screen, stacktrace)
selenium.common.exceptions.WebDriverException: Message: chrome not reachable
  (Session info: chrome=91.0.4472.164)


2021-07-21 09:26:39,528 : basepage.py : ERROR : 请检查定位方式和定位表达式格式是否正确
2021-07-21 09:26:39,528 : basepage.py : ERROR : 请检查定位方式和定位表达式格式是否正确
2021-07-21 09:26:39,529 : basepage.py : ERROR : Traceback (most recent call last):
  File "/Users/liushiwen/PycharmProjects/MyTestFramwoek/UITestObjects/BaseFactory/basepage.py", line 124, in find_element
    return self.driver.find_element(self.locationTypeDict[location_type.lower()], locator_expression)
  File "/Users/liushiwen/.local/lib/python3.8/site-packages/selenium/webdriver/remote/webdriver.py", line 976, in find_element
    return self.execute(Command.FIND_ELEMENT, {
  File "/Users/liushiwen/.local/lib/python3.8/site-packages/selenium/webdriver/remote/webdriver.py", line 321, in execute
    self.error_handler.check_response(response)
  File "/Users/liushiwen/.local/lib/python3.8/site-packages/selenium/webdriver/remote/errorhandler.py", line 242, in check_response
    raise exception_class(message, screen, stacktrace)
selenium.common.exceptions.WebDriverException: Message: chrome not reachable
  (Session info: chrome=91.0.4472.164)


2021-07-21 09:26:39,529 : basepage.py : ERROR : Traceback (most recent call last):
  File "/Users/liushiwen/PycharmProjects/MyTestFramwoek/UITestObjects/BaseFactory/basepage.py", line 124, in find_element
    return self.driver.find_element(self.locationTypeDict[location_type.lower()], locator_expression)
  File "/Users/liushiwen/.local/lib/python3.8/site-packages/selenium/webdriver/remote/webdriver.py", line 976, in find_element
    return self.execute(Command.FIND_ELEMENT, {
  File "/Users/liushiwen/.local/lib/python3.8/site-packages/selenium/webdriver/remote/webdriver.py", line 321, in execute
    self.error_handler.check_response(response)
  File "/Users/liushiwen/.local/lib/python3.8/site-packages/selenium/webdriver/remote/errorhandler.py", line 242, in check_response
    raise exception_class(message, screen, stacktrace)
selenium.common.exceptions.WebDriverException: Message: chrome not reachable
  (Session info: chrome=91.0.4472.164)


2021-07-21 09:26:40,039 : basepage.py : ERROR : 请检查定位方式和定位表达式格式是否正确
2021-07-21 09:26:40,039 : basepage.py : ERROR : 请检查定位方式和定位表达式格式是否正确
2021-07-21 09:26:40,040 : basepage.py : ERROR : Traceback (most recent call last):
  File "/Users/liushiwen/PycharmProjects/MyTestFramwoek/UITestObjects/BaseFactory/basepage.py", line 124, in find_element
    return self.driver.find_element(self.locationTypeDict[location_type.lower()], locator_expression)
  File "/Users/liushiwen/.local/lib/python3.8/site-packages/selenium/webdriver/remote/webdriver.py", line 976, in find_element
    return self.execute(Command.FIND_ELEMENT, {
  File "/Users/liushiwen/.local/lib/python3.8/site-packages/selenium/webdriver/remote/webdriver.py", line 321, in execute
    self.error_handler.check_response(response)
  File "/Users/liushiwen/.local/lib/python3.8/site-packages/selenium/webdriver/remote/errorhandler.py", line 242, in check_response
    raise exception_class(message, screen, stacktrace)
selenium.common.exceptions.WebDriverException: Message: chrome not reachable
  (Session info: chrome=91.0.4472.164)


2021-07-21 09:26:40,040 : basepage.py : ERROR : Traceback (most recent call last):
  File "/Users/liushiwen/PycharmProjects/MyTestFramwoek/UITestObjects/BaseFactory/basepage.py", line 124, in find_element
    return self.driver.find_element(self.locationTypeDict[location_type.lower()], locator_expression)
  File "/Users/liushiwen/.local/lib/python3.8/site-packages/selenium/webdriver/remote/webdriver.py", line 976, in find_element
    return self.execute(Command.FIND_ELEMENT, {
  File "/Users/liushiwen/.local/lib/python3.8/site-packages/selenium/webdriver/remote/webdriver.py", line 321, in execute
    self.error_handler.check_response(response)
  File "/Users/liushiwen/.local/lib/python3.8/site-packages/selenium/webdriver/remote/errorhandler.py", line 242, in check_response
    raise exception_class(message, screen, stacktrace)
selenium.common.exceptions.WebDriverException: Message: chrome not reachable
  (Session info: chrome=91.0.4472.164)


2021-07-21 09:26:40,547 : basepage.py : ERROR : 请检查定位方式和定位表达式格式是否正确
2021-07-21 09:26:40,547 : basepage.py : ERROR : 请检查定位方式和定位表达式格式是否正确
2021-07-21 09:26:40,548 : basepage.py : ERROR : Traceback (most recent call last):
  File "/Users/liushiwen/PycharmProjects/MyTestFramwoek/UITestObjects/BaseFactory/basepage.py", line 124, in find_element
    return self.driver.find_element(self.locationTypeDict[location_type.lower()], locator_expression)
  File "/Users/liushiwen/.local/lib/python3.8/site-packages/selenium/webdriver/remote/webdriver.py", line 976, in find_element
    return self.execute(Command.FIND_ELEMENT, {
  File "/Users/liushiwen/.local/lib/python3.8/site-packages/selenium/webdriver/remote/webdriver.py", line 321, in execute
    self.error_handler.check_response(response)
  File "/Users/liushiwen/.local/lib/python3.8/site-packages/selenium/webdriver/remote/errorhandler.py", line 242, in check_response
    raise exception_class(message, screen, stacktrace)
selenium.common.exceptions.WebDriverException: Message: chrome not reachable
  (Session info: chrome=91.0.4472.164)


2021-07-21 09:26:40,548 : basepage.py : ERROR : Traceback (most recent call last):
  File "/Users/liushiwen/PycharmProjects/MyTestFramwoek/UITestObjects/BaseFactory/basepage.py", line 124, in find_element
    return self.driver.find_element(self.locationTypeDict[location_type.lower()], locator_expression)
  File "/Users/liushiwen/.local/lib/python3.8/site-packages/selenium/webdriver/remote/webdriver.py", line 976, in find_element
    return self.execute(Command.FIND_ELEMENT, {
  File "/Users/liushiwen/.local/lib/python3.8/site-packages/selenium/webdriver/remote/webdriver.py", line 321, in execute
    self.error_handler.check_response(response)
  File "/Users/liushiwen/.local/lib/python3.8/site-packages/selenium/webdriver/remote/errorhandler.py", line 242, in check_response
    raise exception_class(message, screen, stacktrace)
selenium.common.exceptions.WebDriverException: Message: chrome not reachable
  (Session info: chrome=91.0.4472.164)


2021-07-21 09:26:41,055 : basepage.py : ERROR : 请检查定位方式和定位表达式格式是否正确
2021-07-21 09:26:41,055 : basepage.py : ERROR : 请检查定位方式和定位表达式格式是否正确
2021-07-21 09:26:41,055 : basepage.py : ERROR : Traceback (most recent call last):
  File "/Users/liushiwen/PycharmProjects/MyTestFramwoek/UITestObjects/BaseFactory/basepage.py", line 124, in find_element
    return self.driver.find_element(self.locationTypeDict[location_type.lower()], locator_expression)
  File "/Users/liushiwen/.local/lib/python3.8/site-packages/selenium/webdriver/remote/webdriver.py", line 976, in find_element
    return self.execute(Command.FIND_ELEMENT, {
  File "/Users/liushiwen/.local/lib/python3.8/site-packages/selenium/webdriver/remote/webdriver.py", line 321, in execute
    self.error_handler.check_response(response)
  File "/Users/liushiwen/.local/lib/python3.8/site-packages/selenium/webdriver/remote/errorhandler.py", line 242, in check_response
    raise exception_class(message, screen, stacktrace)
selenium.common.exceptions.WebDriverException: Message: chrome not reachable
  (Session info: chrome=91.0.4472.164)


2021-07-21 09:26:41,055 : basepage.py : ERROR : Traceback (most recent call last):
  File "/Users/liushiwen/PycharmProjects/MyTestFramwoek/UITestObjects/BaseFactory/basepage.py", line 124, in find_element
    return self.driver.find_element(self.locationTypeDict[location_type.lower()], locator_expression)
  File "/Users/liushiwen/.local/lib/python3.8/site-packages/selenium/webdriver/remote/webdriver.py", line 976, in find_element
    return self.execute(Command.FIND_ELEMENT, {
  File "/Users/liushiwen/.local/lib/python3.8/site-packages/selenium/webdriver/remote/webdriver.py", line 321, in execute
    self.error_handler.check_response(response)
  File "/Users/liushiwen/.local/lib/python3.8/site-packages/selenium/webdriver/remote/errorhandler.py", line 242, in check_response
    raise exception_class(message, screen, stacktrace)
selenium.common.exceptions.WebDriverException: Message: chrome not reachable
  (Session info: chrome=91.0.4472.164)


2021-07-21 09:26:41,564 : basepage.py : ERROR : 请检查定位方式和定位表达式格式是否正确
2021-07-21 09:26:41,564 : basepage.py : ERROR : 请检查定位方式和定位表达式格式是否正确
2021-07-21 09:26:41,565 : basepage.py : ERROR : Traceback (most recent call last):
  File "/Users/liushiwen/PycharmProjects/MyTestFramwoek/UITestObjects/BaseFactory/basepage.py", line 124, in find_element
    return self.driver.find_element(self.locationTypeDict[location_type.lower()], locator_expression)
  File "/Users/liushiwen/.local/lib/python3.8/site-packages/selenium/webdriver/remote/webdriver.py", line 976, in find_element
    return self.execute(Command.FIND_ELEMENT, {
  File "/Users/liushiwen/.local/lib/python3.8/site-packages/selenium/webdriver/remote/webdriver.py", line 321, in execute
    self.error_handler.check_response(response)
  File "/Users/liushiwen/.local/lib/python3.8/site-packages/selenium/webdriver/remote/errorhandler.py", line 242, in check_response
    raise exception_class(message, screen, stacktrace)
selenium.common.exceptions.WebDriverException: Message: chrome not reachable
  (Session info: chrome=91.0.4472.164)


2021-07-21 09:26:41,565 : basepage.py : ERROR : Traceback (most recent call last):
  File "/Users/liushiwen/PycharmProjects/MyTestFramwoek/UITestObjects/BaseFactory/basepage.py", line 124, in find_element
    return self.driver.find_element(self.locationTypeDict[location_type.lower()], locator_expression)
  File "/Users/liushiwen/.local/lib/python3.8/site-packages/selenium/webdriver/remote/webdriver.py", line 976, in find_element
    return self.execute(Command.FIND_ELEMENT, {
  File "/Users/liushiwen/.local/lib/python3.8/site-packages/selenium/webdriver/remote/webdriver.py", line 321, in execute
    self.error_handler.check_response(response)
  File "/Users/liushiwen/.local/lib/python3.8/site-packages/selenium/webdriver/remote/errorhandler.py", line 242, in check_response
    raise exception_class(message, screen, stacktrace)
selenium.common.exceptions.WebDriverException: Message: chrome not reachable
  (Session info: chrome=91.0.4472.164)


2021-07-21 09:26:42,073 : basepage.py : ERROR : 请检查定位方式和定位表达式格式是否正确
2021-07-21 09:26:42,073 : basepage.py : ERROR : 请检查定位方式和定位表达式格式是否正确
2021-07-21 09:26:42,073 : basepage.py : ERROR : Traceback (most recent call last):
  File "/Users/liushiwen/PycharmProjects/MyTestFramwoek/UITestObjects/BaseFactory/basepage.py", line 124, in find_element
    return self.driver.find_element(self.locationTypeDict[location_type.lower()], locator_expression)
  File "/Users/liushiwen/.local/lib/python3.8/site-packages/selenium/webdriver/remote/webdriver.py", line 976, in find_element
    return self.execute(Command.FIND_ELEMENT, {
  File "/Users/liushiwen/.local/lib/python3.8/site-packages/selenium/webdriver/remote/webdriver.py", line 321, in execute
    self.error_handler.check_response(response)
  File "/Users/liushiwen/.local/lib/python3.8/site-packages/selenium/webdriver/remote/errorhandler.py", line 242, in check_response
    raise exception_class(message, screen, stacktrace)
selenium.common.exceptions.WebDriverException: Message: chrome not reachable
  (Session info: chrome=91.0.4472.164)


2021-07-21 09:26:42,073 : basepage.py : ERROR : Traceback (most recent call last):
  File "/Users/liushiwen/PycharmProjects/MyTestFramwoek/UITestObjects/BaseFactory/basepage.py", line 124, in find_element
    return self.driver.find_element(self.locationTypeDict[location_type.lower()], locator_expression)
  File "/Users/liushiwen/.local/lib/python3.8/site-packages/selenium/webdriver/remote/webdriver.py", line 976, in find_element
    return self.execute(Command.FIND_ELEMENT, {
  File "/Users/liushiwen/.local/lib/python3.8/site-packages/selenium/webdriver/remote/webdriver.py", line 321, in execute
    self.error_handler.check_response(response)
  File "/Users/liushiwen/.local/lib/python3.8/site-packages/selenium/webdriver/remote/errorhandler.py", line 242, in check_response
    raise exception_class(message, screen, stacktrace)
selenium.common.exceptions.WebDriverException: Message: chrome not reachable
  (Session info: chrome=91.0.4472.164)


2021-07-21 09:26:42,580 : basepage.py : ERROR : 请检查定位方式和定位表达式格式是否正确
2021-07-21 09:26:42,580 : basepage.py : ERROR : 请检查定位方式和定位表达式格式是否正确
2021-07-21 09:26:42,581 : basepage.py : ERROR : Traceback (most recent call last):
  File "/Users/liushiwen/PycharmProjects/MyTestFramwoek/UITestObjects/BaseFactory/basepage.py", line 124, in find_element
    return self.driver.find_element(self.locationTypeDict[location_type.lower()], locator_expression)
  File "/Users/liushiwen/.local/lib/python3.8/site-packages/selenium/webdriver/remote/webdriver.py", line 976, in find_element
    return self.execute(Command.FIND_ELEMENT, {
  File "/Users/liushiwen/.local/lib/python3.8/site-packages/selenium/webdriver/remote/webdriver.py", line 321, in execute
    self.error_handler.check_response(response)
  File "/Users/liushiwen/.local/lib/python3.8/site-packages/selenium/webdriver/remote/errorhandler.py", line 242, in check_response
    raise exception_class(message, screen, stacktrace)
selenium.common.exceptions.WebDriverException: Message: chrome not reachable
  (Session info: chrome=91.0.4472.164)


2021-07-21 09:26:42,581 : basepage.py : ERROR : Traceback (most recent call last):
  File "/Users/liushiwen/PycharmProjects/MyTestFramwoek/UITestObjects/BaseFactory/basepage.py", line 124, in find_element
    return self.driver.find_element(self.locationTypeDict[location_type.lower()], locator_expression)
  File "/Users/liushiwen/.local/lib/python3.8/site-packages/selenium/webdriver/remote/webdriver.py", line 976, in find_element
    return self.execute(Command.FIND_ELEMENT, {
  File "/Users/liushiwen/.local/lib/python3.8/site-packages/selenium/webdriver/remote/webdriver.py", line 321, in execute
    self.error_handler.check_response(response)
  File "/Users/liushiwen/.local/lib/python3.8/site-packages/selenium/webdriver/remote/errorhandler.py", line 242, in check_response
    raise exception_class(message, screen, stacktrace)
selenium.common.exceptions.WebDriverException: Message: chrome not reachable
  (Session info: chrome=91.0.4472.164)


2021-07-21 09:26:43,087 : basepage.py : ERROR : 请检查定位方式和定位表达式格式是否正确
2021-07-21 09:26:43,087 : basepage.py : ERROR : 请检查定位方式和定位表达式格式是否正确
2021-07-21 09:26:43,087 : basepage.py : ERROR : Traceback (most recent call last):
  File "/Users/liushiwen/PycharmProjects/MyTestFramwoek/UITestObjects/BaseFactory/basepage.py", line 124, in find_element
    return self.driver.find_element(self.locationTypeDict[location_type.lower()], locator_expression)
  File "/Users/liushiwen/.local/lib/python3.8/site-packages/selenium/webdriver/remote/webdriver.py", line 976, in find_element
    return self.execute(Command.FIND_ELEMENT, {
  File "/Users/liushiwen/.local/lib/python3.8/site-packages/selenium/webdriver/remote/webdriver.py", line 321, in execute
    self.error_handler.check_response(response)
  File "/Users/liushiwen/.local/lib/python3.8/site-packages/selenium/webdriver/remote/errorhandler.py", line 242, in check_response
    raise exception_class(message, screen, stacktrace)
selenium.common.exceptions.WebDriverException: Message: chrome not reachable
  (Session info: chrome=91.0.4472.164)


2021-07-21 09:26:43,087 : basepage.py : ERROR : Traceback (most recent call last):
  File "/Users/liushiwen/PycharmProjects/MyTestFramwoek/UITestObjects/BaseFactory/basepage.py", line 124, in find_element
    return self.driver.find_element(self.locationTypeDict[location_type.lower()], locator_expression)
  File "/Users/liushiwen/.local/lib/python3.8/site-packages/selenium/webdriver/remote/webdriver.py", line 976, in find_element
    return self.execute(Command.FIND_ELEMENT, {
  File "/Users/liushiwen/.local/lib/python3.8/site-packages/selenium/webdriver/remote/webdriver.py", line 321, in execute
    self.error_handler.check_response(response)
  File "/Users/liushiwen/.local/lib/python3.8/site-packages/selenium/webdriver/remote/errorhandler.py", line 242, in check_response
    raise exception_class(message, screen, stacktrace)
selenium.common.exceptions.WebDriverException: Message: chrome not reachable
  (Session info: chrome=91.0.4472.164)


2021-07-21 09:26:43,592 : basepage.py : ERROR : 请检查定位方式和定位表达式格式是否正确
2021-07-21 09:26:43,592 : basepage.py : ERROR : 请检查定位方式和定位表达式格式是否正确
2021-07-21 09:26:43,593 : basepage.py : ERROR : Traceback (most recent call last):
  File "/Users/liushiwen/PycharmProjects/MyTestFramwoek/UITestObjects/BaseFactory/basepage.py", line 124, in find_element
    return self.driver.find_element(self.locationTypeDict[location_type.lower()], locator_expression)
  File "/Users/liushiwen/.local/lib/python3.8/site-packages/selenium/webdriver/remote/webdriver.py", line 976, in find_element
    return self.execute(Command.FIND_ELEMENT, {
  File "/Users/liushiwen/.local/lib/python3.8/site-packages/selenium/webdriver/remote/webdriver.py", line 321, in execute
    self.error_handler.check_response(response)
  File "/Users/liushiwen/.local/lib/python3.8/site-packages/selenium/webdriver/remote/errorhandler.py", line 242, in check_response
    raise exception_class(message, screen, stacktrace)
selenium.common.exceptions.WebDriverException: Message: chrome not reachable
  (Session info: chrome=91.0.4472.164)


2021-07-21 09:26:43,593 : basepage.py : ERROR : Traceback (most recent call last):
  File "/Users/liushiwen/PycharmProjects/MyTestFramwoek/UITestObjects/BaseFactory/basepage.py", line 124, in find_element
    return self.driver.find_element(self.locationTypeDict[location_type.lower()], locator_expression)
  File "/Users/liushiwen/.local/lib/python3.8/site-packages/selenium/webdriver/remote/webdriver.py", line 976, in find_element
    return self.execute(Command.FIND_ELEMENT, {
  File "/Users/liushiwen/.local/lib/python3.8/site-packages/selenium/webdriver/remote/webdriver.py", line 321, in execute
    self.error_handler.check_response(response)
  File "/Users/liushiwen/.local/lib/python3.8/site-packages/selenium/webdriver/remote/errorhandler.py", line 242, in check_response
    raise exception_class(message, screen, stacktrace)
selenium.common.exceptions.WebDriverException: Message: chrome not reachable
  (Session info: chrome=91.0.4472.164)


2021-07-21 09:26:44,102 : basepage.py : ERROR : 请检查定位方式和定位表达式格式是否正确
2021-07-21 09:26:44,102 : basepage.py : ERROR : 请检查定位方式和定位表达式格式是否正确
2021-07-21 09:26:44,103 : basepage.py : ERROR : Traceback (most recent call last):
  File "/Users/liushiwen/PycharmProjects/MyTestFramwoek/UITestObjects/BaseFactory/basepage.py", line 124, in find_element
    return self.driver.find_element(self.locationTypeDict[location_type.lower()], locator_expression)
  File "/Users/liushiwen/.local/lib/python3.8/site-packages/selenium/webdriver/remote/webdriver.py", line 976, in find_element
    return self.execute(Command.FIND_ELEMENT, {
  File "/Users/liushiwen/.local/lib/python3.8/site-packages/selenium/webdriver/remote/webdriver.py", line 321, in execute
    self.error_handler.check_response(response)
  File "/Users/liushiwen/.local/lib/python3.8/site-packages/selenium/webdriver/remote/errorhandler.py", line 242, in check_response
    raise exception_class(message, screen, stacktrace)
selenium.common.exceptions.WebDriverException: Message: chrome not reachable
  (Session info: chrome=91.0.4472.164)


2021-07-21 09:26:44,103 : basepage.py : ERROR : Traceback (most recent call last):
  File "/Users/liushiwen/PycharmProjects/MyTestFramwoek/UITestObjects/BaseFactory/basepage.py", line 124, in find_element
    return self.driver.find_element(self.locationTypeDict[location_type.lower()], locator_expression)
  File "/Users/liushiwen/.local/lib/python3.8/site-packages/selenium/webdriver/remote/webdriver.py", line 976, in find_element
    return self.execute(Command.FIND_ELEMENT, {
  File "/Users/liushiwen/.local/lib/python3.8/site-packages/selenium/webdriver/remote/webdriver.py", line 321, in execute
    self.error_handler.check_response(response)
  File "/Users/liushiwen/.local/lib/python3.8/site-packages/selenium/webdriver/remote/errorhandler.py", line 242, in check_response
    raise exception_class(message, screen, stacktrace)
selenium.common.exceptions.WebDriverException: Message: chrome not reachable
  (Session info: chrome=91.0.4472.164)


2021-07-21 09:26:44,613 : basepage.py : ERROR : 请检查定位方式和定位表达式格式是否正确
2021-07-21 09:26:44,613 : basepage.py : ERROR : 请检查定位方式和定位表达式格式是否正确
2021-07-21 09:26:44,614 : basepage.py : ERROR : Traceback (most recent call last):
  File "/Users/liushiwen/PycharmProjects/MyTestFramwoek/UITestObjects/BaseFactory/basepage.py", line 124, in find_element
    return self.driver.find_element(self.locationTypeDict[location_type.lower()], locator_expression)
  File "/Users/liushiwen/.local/lib/python3.8/site-packages/selenium/webdriver/remote/webdriver.py", line 976, in find_element
    return self.execute(Command.FIND_ELEMENT, {
  File "/Users/liushiwen/.local/lib/python3.8/site-packages/selenium/webdriver/remote/webdriver.py", line 321, in execute
    self.error_handler.check_response(response)
  File "/Users/liushiwen/.local/lib/python3.8/site-packages/selenium/webdriver/remote/errorhandler.py", line 242, in check_response
    raise exception_class(message, screen, stacktrace)
selenium.common.exceptions.WebDriverException: Message: chrome not reachable
  (Session info: chrome=91.0.4472.164)


2021-07-21 09:26:44,614 : basepage.py : ERROR : Traceback (most recent call last):
  File "/Users/liushiwen/PycharmProjects/MyTestFramwoek/UITestObjects/BaseFactory/basepage.py", line 124, in find_element
    return self.driver.find_element(self.locationTypeDict[location_type.lower()], locator_expression)
  File "/Users/liushiwen/.local/lib/python3.8/site-packages/selenium/webdriver/remote/webdriver.py", line 976, in find_element
    return self.execute(Command.FIND_ELEMENT, {
  File "/Users/liushiwen/.local/lib/python3.8/site-packages/selenium/webdriver/remote/webdriver.py", line 321, in execute
    self.error_handler.check_response(response)
  File "/Users/liushiwen/.local/lib/python3.8/site-packages/selenium/webdriver/remote/errorhandler.py", line 242, in check_response
    raise exception_class(message, screen, stacktrace)
selenium.common.exceptions.WebDriverException: Message: chrome not reachable
  (Session info: chrome=91.0.4472.164)


2021-07-21 09:26:45,117 : basepage.py : ERROR : 请检查定位方式和定位表达式格式是否正确
2021-07-21 09:26:45,117 : basepage.py : ERROR : 请检查定位方式和定位表达式格式是否正确
2021-07-21 09:26:45,117 : basepage.py : ERROR : Traceback (most recent call last):
  File "/Users/liushiwen/PycharmProjects/MyTestFramwoek/UITestObjects/BaseFactory/basepage.py", line 124, in find_element
    return self.driver.find_element(self.locationTypeDict[location_type.lower()], locator_expression)
  File "/Users/liushiwen/.local/lib/python3.8/site-packages/selenium/webdriver/remote/webdriver.py", line 976, in find_element
    return self.execute(Command.FIND_ELEMENT, {
  File "/Users/liushiwen/.local/lib/python3.8/site-packages/selenium/webdriver/remote/webdriver.py", line 321, in execute
    self.error_handler.check_response(response)
  File "/Users/liushiwen/.local/lib/python3.8/site-packages/selenium/webdriver/remote/errorhandler.py", line 242, in check_response
    raise exception_class(message, screen, stacktrace)
selenium.common.exceptions.WebDriverException: Message: chrome not reachable
  (Session info: chrome=91.0.4472.164)


2021-07-21 09:26:45,117 : basepage.py : ERROR : Traceback (most recent call last):
  File "/Users/liushiwen/PycharmProjects/MyTestFramwoek/UITestObjects/BaseFactory/basepage.py", line 124, in find_element
    return self.driver.find_element(self.locationTypeDict[location_type.lower()], locator_expression)
  File "/Users/liushiwen/.local/lib/python3.8/site-packages/selenium/webdriver/remote/webdriver.py", line 976, in find_element
    return self.execute(Command.FIND_ELEMENT, {
  File "/Users/liushiwen/.local/lib/python3.8/site-packages/selenium/webdriver/remote/webdriver.py", line 321, in execute
    self.error_handler.check_response(response)
  File "/Users/liushiwen/.local/lib/python3.8/site-packages/selenium/webdriver/remote/errorhandler.py", line 242, in check_response
    raise exception_class(message, screen, stacktrace)
selenium.common.exceptions.WebDriverException: Message: chrome not reachable
  (Session info: chrome=91.0.4472.164)


2021-07-21 09:26:45,631 : basepage.py : ERROR : 请检查定位方式和定位表达式格式是否正确
2021-07-21 09:26:45,631 : basepage.py : ERROR : 请检查定位方式和定位表达式格式是否正确
2021-07-21 09:26:45,632 : basepage.py : ERROR : Traceback (most recent call last):
  File "/Users/liushiwen/PycharmProjects/MyTestFramwoek/UITestObjects/BaseFactory/basepage.py", line 124, in find_element
    return self.driver.find_element(self.locationTypeDict[location_type.lower()], locator_expression)
  File "/Users/liushiwen/.local/lib/python3.8/site-packages/selenium/webdriver/remote/webdriver.py", line 976, in find_element
    return self.execute(Command.FIND_ELEMENT, {
  File "/Users/liushiwen/.local/lib/python3.8/site-packages/selenium/webdriver/remote/webdriver.py", line 321, in execute
    self.error_handler.check_response(response)
  File "/Users/liushiwen/.local/lib/python3.8/site-packages/selenium/webdriver/remote/errorhandler.py", line 242, in check_response
    raise exception_class(message, screen, stacktrace)
selenium.common.exceptions.WebDriverException: Message: chrome not reachable
  (Session info: chrome=91.0.4472.164)


2021-07-21 09:26:45,632 : basepage.py : ERROR : Traceback (most recent call last):
  File "/Users/liushiwen/PycharmProjects/MyTestFramwoek/UITestObjects/BaseFactory/basepage.py", line 124, in find_element
    return self.driver.find_element(self.locationTypeDict[location_type.lower()], locator_expression)
  File "/Users/liushiwen/.local/lib/python3.8/site-packages/selenium/webdriver/remote/webdriver.py", line 976, in find_element
    return self.execute(Command.FIND_ELEMENT, {
  File "/Users/liushiwen/.local/lib/python3.8/site-packages/selenium/webdriver/remote/webdriver.py", line 321, in execute
    self.error_handler.check_response(response)
  File "/Users/liushiwen/.local/lib/python3.8/site-packages/selenium/webdriver/remote/errorhandler.py", line 242, in check_response
    raise exception_class(message, screen, stacktrace)
selenium.common.exceptions.WebDriverException: Message: chrome not reachable
  (Session info: chrome=91.0.4472.164)


2021-07-21 09:26:46,145 : basepage.py : ERROR : 请检查定位方式和定位表达式格式是否正确
2021-07-21 09:26:46,145 : basepage.py : ERROR : 请检查定位方式和定位表达式格式是否正确
2021-07-21 09:26:46,146 : basepage.py : ERROR : Traceback (most recent call last):
  File "/Users/liushiwen/PycharmProjects/MyTestFramwoek/UITestObjects/BaseFactory/basepage.py", line 124, in find_element
    return self.driver.find_element(self.locationTypeDict[location_type.lower()], locator_expression)
  File "/Users/liushiwen/.local/lib/python3.8/site-packages/selenium/webdriver/remote/webdriver.py", line 976, in find_element
    return self.execute(Command.FIND_ELEMENT, {
  File "/Users/liushiwen/.local/lib/python3.8/site-packages/selenium/webdriver/remote/webdriver.py", line 321, in execute
    self.error_handler.check_response(response)
  File "/Users/liushiwen/.local/lib/python3.8/site-packages/selenium/webdriver/remote/errorhandler.py", line 242, in check_response
    raise exception_class(message, screen, stacktrace)
selenium.common.exceptions.WebDriverException: Message: chrome not reachable
  (Session info: chrome=91.0.4472.164)


2021-07-21 09:26:46,146 : basepage.py : ERROR : Traceback (most recent call last):
  File "/Users/liushiwen/PycharmProjects/MyTestFramwoek/UITestObjects/BaseFactory/basepage.py", line 124, in find_element
    return self.driver.find_element(self.locationTypeDict[location_type.lower()], locator_expression)
  File "/Users/liushiwen/.local/lib/python3.8/site-packages/selenium/webdriver/remote/webdriver.py", line 976, in find_element
    return self.execute(Command.FIND_ELEMENT, {
  File "/Users/liushiwen/.local/lib/python3.8/site-packages/selenium/webdriver/remote/webdriver.py", line 321, in execute
    self.error_handler.check_response(response)
  File "/Users/liushiwen/.local/lib/python3.8/site-packages/selenium/webdriver/remote/errorhandler.py", line 242, in check_response
    raise exception_class(message, screen, stacktrace)
selenium.common.exceptions.WebDriverException: Message: chrome not reachable
  (Session info: chrome=91.0.4472.164)


2021-07-21 09:26:46,652 : basepage.py : ERROR : 请检查定位方式和定位表达式格式是否正确
2021-07-21 09:26:46,652 : basepage.py : ERROR : 请检查定位方式和定位表达式格式是否正确
2021-07-21 09:26:46,652 : basepage.py : ERROR : Traceback (most recent call last):
  File "/Users/liushiwen/PycharmProjects/MyTestFramwoek/UITestObjects/BaseFactory/basepage.py", line 124, in find_element
    return self.driver.find_element(self.locationTypeDict[location_type.lower()], locator_expression)
  File "/Users/liushiwen/.local/lib/python3.8/site-packages/selenium/webdriver/remote/webdriver.py", line 976, in find_element
    return self.execute(Command.FIND_ELEMENT, {
  File "/Users/liushiwen/.local/lib/python3.8/site-packages/selenium/webdriver/remote/webdriver.py", line 321, in execute
    self.error_handler.check_response(response)
  File "/Users/liushiwen/.local/lib/python3.8/site-packages/selenium/webdriver/remote/errorhandler.py", line 242, in check_response
    raise exception_class(message, screen, stacktrace)
selenium.common.exceptions.WebDriverException: Message: chrome not reachable
  (Session info: chrome=91.0.4472.164)


2021-07-21 09:26:46,652 : basepage.py : ERROR : Traceback (most recent call last):
  File "/Users/liushiwen/PycharmProjects/MyTestFramwoek/UITestObjects/BaseFactory/basepage.py", line 124, in find_element
    return self.driver.find_element(self.locationTypeDict[location_type.lower()], locator_expression)
  File "/Users/liushiwen/.local/lib/python3.8/site-packages/selenium/webdriver/remote/webdriver.py", line 976, in find_element
    return self.execute(Command.FIND_ELEMENT, {
  File "/Users/liushiwen/.local/lib/python3.8/site-packages/selenium/webdriver/remote/webdriver.py", line 321, in execute
    self.error_handler.check_response(response)
  File "/Users/liushiwen/.local/lib/python3.8/site-packages/selenium/webdriver/remote/errorhandler.py", line 242, in check_response
    raise exception_class(message, screen, stacktrace)
selenium.common.exceptions.WebDriverException: Message: chrome not reachable
  (Session info: chrome=91.0.4472.164)


2021-07-21 09:26:47,158 : basepage.py : ERROR : 请检查定位方式和定位表达式格式是否正确
2021-07-21 09:26:47,158 : basepage.py : ERROR : 请检查定位方式和定位表达式格式是否正确
2021-07-21 09:26:47,159 : basepage.py : ERROR : Traceback (most recent call last):
  File "/Users/liushiwen/PycharmProjects/MyTestFramwoek/UITestObjects/BaseFactory/basepage.py", line 124, in find_element
    return self.driver.find_element(self.locationTypeDict[location_type.lower()], locator_expression)
  File "/Users/liushiwen/.local/lib/python3.8/site-packages/selenium/webdriver/remote/webdriver.py", line 976, in find_element
    return self.execute(Command.FIND_ELEMENT, {
  File "/Users/liushiwen/.local/lib/python3.8/site-packages/selenium/webdriver/remote/webdriver.py", line 321, in execute
    self.error_handler.check_response(response)
  File "/Users/liushiwen/.local/lib/python3.8/site-packages/selenium/webdriver/remote/errorhandler.py", line 242, in check_response
    raise exception_class(message, screen, stacktrace)
selenium.common.exceptions.WebDriverException: Message: chrome not reachable
  (Session info: chrome=91.0.4472.164)


2021-07-21 09:26:47,159 : basepage.py : ERROR : Traceback (most recent call last):
  File "/Users/liushiwen/PycharmProjects/MyTestFramwoek/UITestObjects/BaseFactory/basepage.py", line 124, in find_element
    return self.driver.find_element(self.locationTypeDict[location_type.lower()], locator_expression)
  File "/Users/liushiwen/.local/lib/python3.8/site-packages/selenium/webdriver/remote/webdriver.py", line 976, in find_element
    return self.execute(Command.FIND_ELEMENT, {
  File "/Users/liushiwen/.local/lib/python3.8/site-packages/selenium/webdriver/remote/webdriver.py", line 321, in execute
    self.error_handler.check_response(response)
  File "/Users/liushiwen/.local/lib/python3.8/site-packages/selenium/webdriver/remote/errorhandler.py", line 242, in check_response
    raise exception_class(message, screen, stacktrace)
selenium.common.exceptions.WebDriverException: Message: chrome not reachable
  (Session info: chrome=91.0.4472.164)


2021-07-21 09:26:47,668 : basepage.py : ERROR : 请检查定位方式和定位表达式格式是否正确
2021-07-21 09:26:47,668 : basepage.py : ERROR : 请检查定位方式和定位表达式格式是否正确
2021-07-21 09:26:47,669 : basepage.py : ERROR : Traceback (most recent call last):
  File "/Users/liushiwen/PycharmProjects/MyTestFramwoek/UITestObjects/BaseFactory/basepage.py", line 124, in find_element
    return self.driver.find_element(self.locationTypeDict[location_type.lower()], locator_expression)
  File "/Users/liushiwen/.local/lib/python3.8/site-packages/selenium/webdriver/remote/webdriver.py", line 976, in find_element
    return self.execute(Command.FIND_ELEMENT, {
  File "/Users/liushiwen/.local/lib/python3.8/site-packages/selenium/webdriver/remote/webdriver.py", line 321, in execute
    self.error_handler.check_response(response)
  File "/Users/liushiwen/.local/lib/python3.8/site-packages/selenium/webdriver/remote/errorhandler.py", line 242, in check_response
    raise exception_class(message, screen, stacktrace)
selenium.common.exceptions.WebDriverException: Message: chrome not reachable
  (Session info: chrome=91.0.4472.164)


2021-07-21 09:26:47,669 : basepage.py : ERROR : Traceback (most recent call last):
  File "/Users/liushiwen/PycharmProjects/MyTestFramwoek/UITestObjects/BaseFactory/basepage.py", line 124, in find_element
    return self.driver.find_element(self.locationTypeDict[location_type.lower()], locator_expression)
  File "/Users/liushiwen/.local/lib/python3.8/site-packages/selenium/webdriver/remote/webdriver.py", line 976, in find_element
    return self.execute(Command.FIND_ELEMENT, {
  File "/Users/liushiwen/.local/lib/python3.8/site-packages/selenium/webdriver/remote/webdriver.py", line 321, in execute
    self.error_handler.check_response(response)
  File "/Users/liushiwen/.local/lib/python3.8/site-packages/selenium/webdriver/remote/errorhandler.py", line 242, in check_response
    raise exception_class(message, screen, stacktrace)
selenium.common.exceptions.WebDriverException: Message: chrome not reachable
  (Session info: chrome=91.0.4472.164)


2021-07-21 09:26:48,180 : basepage.py : ERROR : 请检查定位方式和定位表达式格式是否正确
2021-07-21 09:26:48,180 : basepage.py : ERROR : 请检查定位方式和定位表达式格式是否正确
2021-07-21 09:26:48,181 : basepage.py : ERROR : Traceback (most recent call last):
  File "/Users/liushiwen/PycharmProjects/MyTestFramwoek/UITestObjects/BaseFactory/basepage.py", line 124, in find_element
    return self.driver.find_element(self.locationTypeDict[location_type.lower()], locator_expression)
  File "/Users/liushiwen/.local/lib/python3.8/site-packages/selenium/webdriver/remote/webdriver.py", line 976, in find_element
    return self.execute(Command.FIND_ELEMENT, {
  File "/Users/liushiwen/.local/lib/python3.8/site-packages/selenium/webdriver/remote/webdriver.py", line 321, in execute
    self.error_handler.check_response(response)
  File "/Users/liushiwen/.local/lib/python3.8/site-packages/selenium/webdriver/remote/errorhandler.py", line 242, in check_response
    raise exception_class(message, screen, stacktrace)
selenium.common.exceptions.WebDriverException: Message: chrome not reachable
  (Session info: chrome=91.0.4472.164)


2021-07-21 09:26:48,181 : basepage.py : ERROR : Traceback (most recent call last):
  File "/Users/liushiwen/PycharmProjects/MyTestFramwoek/UITestObjects/BaseFactory/basepage.py", line 124, in find_element
    return self.driver.find_element(self.locationTypeDict[location_type.lower()], locator_expression)
  File "/Users/liushiwen/.local/lib/python3.8/site-packages/selenium/webdriver/remote/webdriver.py", line 976, in find_element
    return self.execute(Command.FIND_ELEMENT, {
  File "/Users/liushiwen/.local/lib/python3.8/site-packages/selenium/webdriver/remote/webdriver.py", line 321, in execute
    self.error_handler.check_response(response)
  File "/Users/liushiwen/.local/lib/python3.8/site-packages/selenium/webdriver/remote/errorhandler.py", line 242, in check_response
    raise exception_class(message, screen, stacktrace)
selenium.common.exceptions.WebDriverException: Message: chrome not reachable
  (Session info: chrome=91.0.4472.164)


2021-07-21 09:26:48,689 : basepage.py : ERROR : 请检查定位方式和定位表达式格式是否正确
2021-07-21 09:26:48,689 : basepage.py : ERROR : 请检查定位方式和定位表达式格式是否正确
2021-07-21 09:26:48,689 : basepage.py : ERROR : Traceback (most recent call last):
  File "/Users/liushiwen/PycharmProjects/MyTestFramwoek/UITestObjects/BaseFactory/basepage.py", line 124, in find_element
    return self.driver.find_element(self.locationTypeDict[location_type.lower()], locator_expression)
  File "/Users/liushiwen/.local/lib/python3.8/site-packages/selenium/webdriver/remote/webdriver.py", line 976, in find_element
    return self.execute(Command.FIND_ELEMENT, {
  File "/Users/liushiwen/.local/lib/python3.8/site-packages/selenium/webdriver/remote/webdriver.py", line 321, in execute
    self.error_handler.check_response(response)
  File "/Users/liushiwen/.local/lib/python3.8/site-packages/selenium/webdriver/remote/errorhandler.py", line 242, in check_response
    raise exception_class(message, screen, stacktrace)
selenium.common.exceptions.WebDriverException: Message: chrome not reachable
  (Session info: chrome=91.0.4472.164)


2021-07-21 09:26:48,689 : basepage.py : ERROR : Traceback (most recent call last):
  File "/Users/liushiwen/PycharmProjects/MyTestFramwoek/UITestObjects/BaseFactory/basepage.py", line 124, in find_element
    return self.driver.find_element(self.locationTypeDict[location_type.lower()], locator_expression)
  File "/Users/liushiwen/.local/lib/python3.8/site-packages/selenium/webdriver/remote/webdriver.py", line 976, in find_element
    return self.execute(Command.FIND_ELEMENT, {
  File "/Users/liushiwen/.local/lib/python3.8/site-packages/selenium/webdriver/remote/webdriver.py", line 321, in execute
    self.error_handler.check_response(response)
  File "/Users/liushiwen/.local/lib/python3.8/site-packages/selenium/webdriver/remote/errorhandler.py", line 242, in check_response
    raise exception_class(message, screen, stacktrace)
selenium.common.exceptions.WebDriverException: Message: chrome not reachable
  (Session info: chrome=91.0.4472.164)


2021-07-21 09:26:49,196 : basepage.py : ERROR : 请检查定位方式和定位表达式格式是否正确
2021-07-21 09:26:49,196 : basepage.py : ERROR : 请检查定位方式和定位表达式格式是否正确
2021-07-21 09:26:49,196 : basepage.py : ERROR : Traceback (most recent call last):
  File "/Users/liushiwen/PycharmProjects/MyTestFramwoek/UITestObjects/BaseFactory/basepage.py", line 124, in find_element
    return self.driver.find_element(self.locationTypeDict[location_type.lower()], locator_expression)
  File "/Users/liushiwen/.local/lib/python3.8/site-packages/selenium/webdriver/remote/webdriver.py", line 976, in find_element
    return self.execute(Command.FIND_ELEMENT, {
  File "/Users/liushiwen/.local/lib/python3.8/site-packages/selenium/webdriver/remote/webdriver.py", line 321, in execute
    self.error_handler.check_response(response)
  File "/Users/liushiwen/.local/lib/python3.8/site-packages/selenium/webdriver/remote/errorhandler.py", line 242, in check_response
    raise exception_class(message, screen, stacktrace)
selenium.common.exceptions.WebDriverException: Message: chrome not reachable
  (Session info: chrome=91.0.4472.164)


2021-07-21 09:26:49,196 : basepage.py : ERROR : Traceback (most recent call last):
  File "/Users/liushiwen/PycharmProjects/MyTestFramwoek/UITestObjects/BaseFactory/basepage.py", line 124, in find_element
    return self.driver.find_element(self.locationTypeDict[location_type.lower()], locator_expression)
  File "/Users/liushiwen/.local/lib/python3.8/site-packages/selenium/webdriver/remote/webdriver.py", line 976, in find_element
    return self.execute(Command.FIND_ELEMENT, {
  File "/Users/liushiwen/.local/lib/python3.8/site-packages/selenium/webdriver/remote/webdriver.py", line 321, in execute
    self.error_handler.check_response(response)
  File "/Users/liushiwen/.local/lib/python3.8/site-packages/selenium/webdriver/remote/errorhandler.py", line 242, in check_response
    raise exception_class(message, screen, stacktrace)
selenium.common.exceptions.WebDriverException: Message: chrome not reachable
  (Session info: chrome=91.0.4472.164)


2021-07-21 09:26:49,705 : basepage.py : ERROR : 请检查定位方式和定位表达式格式是否正确
2021-07-21 09:26:49,705 : basepage.py : ERROR : 请检查定位方式和定位表达式格式是否正确
2021-07-21 09:26:49,705 : basepage.py : ERROR : Traceback (most recent call last):
  File "/Users/liushiwen/PycharmProjects/MyTestFramwoek/UITestObjects/BaseFactory/basepage.py", line 124, in find_element
    return self.driver.find_element(self.locationTypeDict[location_type.lower()], locator_expression)
  File "/Users/liushiwen/.local/lib/python3.8/site-packages/selenium/webdriver/remote/webdriver.py", line 976, in find_element
    return self.execute(Command.FIND_ELEMENT, {
  File "/Users/liushiwen/.local/lib/python3.8/site-packages/selenium/webdriver/remote/webdriver.py", line 321, in execute
    self.error_handler.check_response(response)
  File "/Users/liushiwen/.local/lib/python3.8/site-packages/selenium/webdriver/remote/errorhandler.py", line 242, in check_response
    raise exception_class(message, screen, stacktrace)
selenium.common.exceptions.WebDriverException: Message: chrome not reachable
  (Session info: chrome=91.0.4472.164)


2021-07-21 09:26:49,705 : basepage.py : ERROR : Traceback (most recent call last):
  File "/Users/liushiwen/PycharmProjects/MyTestFramwoek/UITestObjects/BaseFactory/basepage.py", line 124, in find_element
    return self.driver.find_element(self.locationTypeDict[location_type.lower()], locator_expression)
  File "/Users/liushiwen/.local/lib/python3.8/site-packages/selenium/webdriver/remote/webdriver.py", line 976, in find_element
    return self.execute(Command.FIND_ELEMENT, {
  File "/Users/liushiwen/.local/lib/python3.8/site-packages/selenium/webdriver/remote/webdriver.py", line 321, in execute
    self.error_handler.check_response(response)
  File "/Users/liushiwen/.local/lib/python3.8/site-packages/selenium/webdriver/remote/errorhandler.py", line 242, in check_response
    raise exception_class(message, screen, stacktrace)
selenium.common.exceptions.WebDriverException: Message: chrome not reachable
  (Session info: chrome=91.0.4472.164)


2021-07-21 09:26:50,213 : basepage.py : ERROR : 请检查定位方式和定位表达式格式是否正确
2021-07-21 09:26:50,213 : basepage.py : ERROR : 请检查定位方式和定位表达式格式是否正确
2021-07-21 09:26:50,214 : basepage.py : ERROR : Traceback (most recent call last):
  File "/Users/liushiwen/PycharmProjects/MyTestFramwoek/UITestObjects/BaseFactory/basepage.py", line 124, in find_element
    return self.driver.find_element(self.locationTypeDict[location_type.lower()], locator_expression)
  File "/Users/liushiwen/.local/lib/python3.8/site-packages/selenium/webdriver/remote/webdriver.py", line 976, in find_element
    return self.execute(Command.FIND_ELEMENT, {
  File "/Users/liushiwen/.local/lib/python3.8/site-packages/selenium/webdriver/remote/webdriver.py", line 321, in execute
    self.error_handler.check_response(response)
  File "/Users/liushiwen/.local/lib/python3.8/site-packages/selenium/webdriver/remote/errorhandler.py", line 242, in check_response
    raise exception_class(message, screen, stacktrace)
selenium.common.exceptions.WebDriverException: Message: chrome not reachable
  (Session info: chrome=91.0.4472.164)


2021-07-21 09:26:50,214 : basepage.py : ERROR : Traceback (most recent call last):
  File "/Users/liushiwen/PycharmProjects/MyTestFramwoek/UITestObjects/BaseFactory/basepage.py", line 124, in find_element
    return self.driver.find_element(self.locationTypeDict[location_type.lower()], locator_expression)
  File "/Users/liushiwen/.local/lib/python3.8/site-packages/selenium/webdriver/remote/webdriver.py", line 976, in find_element
    return self.execute(Command.FIND_ELEMENT, {
  File "/Users/liushiwen/.local/lib/python3.8/site-packages/selenium/webdriver/remote/webdriver.py", line 321, in execute
    self.error_handler.check_response(response)
  File "/Users/liushiwen/.local/lib/python3.8/site-packages/selenium/webdriver/remote/errorhandler.py", line 242, in check_response
    raise exception_class(message, screen, stacktrace)
selenium.common.exceptions.WebDriverException: Message: chrome not reachable
  (Session info: chrome=91.0.4472.164)


2021-07-21 09:26:50,726 : basepage.py : ERROR : 请检查定位方式和定位表达式格式是否正确
2021-07-21 09:26:50,726 : basepage.py : ERROR : 请检查定位方式和定位表达式格式是否正确
2021-07-21 09:26:50,727 : basepage.py : ERROR : Traceback (most recent call last):
  File "/Users/liushiwen/PycharmProjects/MyTestFramwoek/UITestObjects/BaseFactory/basepage.py", line 124, in find_element
    return self.driver.find_element(self.locationTypeDict[location_type.lower()], locator_expression)
  File "/Users/liushiwen/.local/lib/python3.8/site-packages/selenium/webdriver/remote/webdriver.py", line 976, in find_element
    return self.execute(Command.FIND_ELEMENT, {
  File "/Users/liushiwen/.local/lib/python3.8/site-packages/selenium/webdriver/remote/webdriver.py", line 321, in execute
    self.error_handler.check_response(response)
  File "/Users/liushiwen/.local/lib/python3.8/site-packages/selenium/webdriver/remote/errorhandler.py", line 242, in check_response
    raise exception_class(message, screen, stacktrace)
selenium.common.exceptions.WebDriverException: Message: chrome not reachable
  (Session info: chrome=91.0.4472.164)


2021-07-21 09:26:50,727 : basepage.py : ERROR : Traceback (most recent call last):
  File "/Users/liushiwen/PycharmProjects/MyTestFramwoek/UITestObjects/BaseFactory/basepage.py", line 124, in find_element
    return self.driver.find_element(self.locationTypeDict[location_type.lower()], locator_expression)
  File "/Users/liushiwen/.local/lib/python3.8/site-packages/selenium/webdriver/remote/webdriver.py", line 976, in find_element
    return self.execute(Command.FIND_ELEMENT, {
  File "/Users/liushiwen/.local/lib/python3.8/site-packages/selenium/webdriver/remote/webdriver.py", line 321, in execute
    self.error_handler.check_response(response)
  File "/Users/liushiwen/.local/lib/python3.8/site-packages/selenium/webdriver/remote/errorhandler.py", line 242, in check_response
    raise exception_class(message, screen, stacktrace)
selenium.common.exceptions.WebDriverException: Message: chrome not reachable
  (Session info: chrome=91.0.4472.164)


2021-07-21 09:26:51,241 : basepage.py : ERROR : 请检查定位方式和定位表达式格式是否正确
2021-07-21 09:26:51,241 : basepage.py : ERROR : 请检查定位方式和定位表达式格式是否正确
2021-07-21 09:26:51,242 : basepage.py : ERROR : Traceback (most recent call last):
  File "/Users/liushiwen/PycharmProjects/MyTestFramwoek/UITestObjects/BaseFactory/basepage.py", line 124, in find_element
    return self.driver.find_element(self.locationTypeDict[location_type.lower()], locator_expression)
  File "/Users/liushiwen/.local/lib/python3.8/site-packages/selenium/webdriver/remote/webdriver.py", line 976, in find_element
    return self.execute(Command.FIND_ELEMENT, {
  File "/Users/liushiwen/.local/lib/python3.8/site-packages/selenium/webdriver/remote/webdriver.py", line 321, in execute
    self.error_handler.check_response(response)
  File "/Users/liushiwen/.local/lib/python3.8/site-packages/selenium/webdriver/remote/errorhandler.py", line 242, in check_response
    raise exception_class(message, screen, stacktrace)
selenium.common.exceptions.WebDriverException: Message: chrome not reachable
  (Session info: chrome=91.0.4472.164)


2021-07-21 09:26:51,242 : basepage.py : ERROR : Traceback (most recent call last):
  File "/Users/liushiwen/PycharmProjects/MyTestFramwoek/UITestObjects/BaseFactory/basepage.py", line 124, in find_element
    return self.driver.find_element(self.locationTypeDict[location_type.lower()], locator_expression)
  File "/Users/liushiwen/.local/lib/python3.8/site-packages/selenium/webdriver/remote/webdriver.py", line 976, in find_element
    return self.execute(Command.FIND_ELEMENT, {
  File "/Users/liushiwen/.local/lib/python3.8/site-packages/selenium/webdriver/remote/webdriver.py", line 321, in execute
    self.error_handler.check_response(response)
  File "/Users/liushiwen/.local/lib/python3.8/site-packages/selenium/webdriver/remote/errorhandler.py", line 242, in check_response
    raise exception_class(message, screen, stacktrace)
selenium.common.exceptions.WebDriverException: Message: chrome not reachable
  (Session info: chrome=91.0.4472.164)


2021-07-21 09:26:51,754 : basepage.py : ERROR : 请检查定位方式和定位表达式格式是否正确
2021-07-21 09:26:51,754 : basepage.py : ERROR : 请检查定位方式和定位表达式格式是否正确
2021-07-21 09:26:51,755 : basepage.py : ERROR : Traceback (most recent call last):
  File "/Users/liushiwen/PycharmProjects/MyTestFramwoek/UITestObjects/BaseFactory/basepage.py", line 124, in find_element
    return self.driver.find_element(self.locationTypeDict[location_type.lower()], locator_expression)
  File "/Users/liushiwen/.local/lib/python3.8/site-packages/selenium/webdriver/remote/webdriver.py", line 976, in find_element
    return self.execute(Command.FIND_ELEMENT, {
  File "/Users/liushiwen/.local/lib/python3.8/site-packages/selenium/webdriver/remote/webdriver.py", line 321, in execute
    self.error_handler.check_response(response)
  File "/Users/liushiwen/.local/lib/python3.8/site-packages/selenium/webdriver/remote/errorhandler.py", line 242, in check_response
    raise exception_class(message, screen, stacktrace)
selenium.common.exceptions.WebDriverException: Message: chrome not reachable
  (Session info: chrome=91.0.4472.164)


2021-07-21 09:26:51,755 : basepage.py : ERROR : Traceback (most recent call last):
  File "/Users/liushiwen/PycharmProjects/MyTestFramwoek/UITestObjects/BaseFactory/basepage.py", line 124, in find_element
    return self.driver.find_element(self.locationTypeDict[location_type.lower()], locator_expression)
  File "/Users/liushiwen/.local/lib/python3.8/site-packages/selenium/webdriver/remote/webdriver.py", line 976, in find_element
    return self.execute(Command.FIND_ELEMENT, {
  File "/Users/liushiwen/.local/lib/python3.8/site-packages/selenium/webdriver/remote/webdriver.py", line 321, in execute
    self.error_handler.check_response(response)
  File "/Users/liushiwen/.local/lib/python3.8/site-packages/selenium/webdriver/remote/errorhandler.py", line 242, in check_response
    raise exception_class(message, screen, stacktrace)
selenium.common.exceptions.WebDriverException: Message: chrome not reachable
  (Session info: chrome=91.0.4472.164)


2021-07-21 09:26:52,259 : accordingWait.py : ERROR : Traceback (most recent call last):
  File "/Users/liushiwen/PycharmProjects/MyTestFramwoek/Common/accordingWait.py", line 82, in presence_of_element_located
    self._wait.until(
  File "/Users/liushiwen/.local/lib/python3.8/site-packages/selenium/webdriver/support/wait.py", line 80, in until
    raise TimeoutException(message, screen, stacktrace)
selenium.common.exceptions.TimeoutException: Message: 


2021-07-21 09:26:52,259 : accordingWait.py : ERROR : Traceback (most recent call last):
  File "/Users/liushiwen/PycharmProjects/MyTestFramwoek/Common/accordingWait.py", line 82, in presence_of_element_located
    self._wait.until(
  File "/Users/liushiwen/.local/lib/python3.8/site-packages/selenium/webdriver/support/wait.py", line 80, in until
    raise TimeoutException(message, screen, stacktrace)
selenium.common.exceptions.TimeoutException: Message: 


2021-07-21 09:26:52,263 : basepage.py : ERROR : 请检查定位方式和定位表达式格式是否正确
2021-07-21 09:26:52,263 : basepage.py : ERROR : 请检查定位方式和定位表达式格式是否正确
2021-07-21 09:26:52,264 : basepage.py : ERROR : Traceback (most recent call last):
  File "/Users/liushiwen/PycharmProjects/MyTestFramwoek/UITestObjects/BaseFactory/basepage.py", line 124, in find_element
    return self.driver.find_element(self.locationTypeDict[location_type.lower()], locator_expression)
  File "/Users/liushiwen/.local/lib/python3.8/site-packages/selenium/webdriver/remote/webdriver.py", line 976, in find_element
    return self.execute(Command.FIND_ELEMENT, {
  File "/Users/liushiwen/.local/lib/python3.8/site-packages/selenium/webdriver/remote/webdriver.py", line 321, in execute
    self.error_handler.check_response(response)
  File "/Users/liushiwen/.local/lib/python3.8/site-packages/selenium/webdriver/remote/errorhandler.py", line 242, in check_response
    raise exception_class(message, screen, stacktrace)
selenium.common.exceptions.WebDriverException: Message: chrome not reachable
  (Session info: chrome=91.0.4472.164)


2021-07-21 09:26:52,264 : basepage.py : ERROR : Traceback (most recent call last):
  File "/Users/liushiwen/PycharmProjects/MyTestFramwoek/UITestObjects/BaseFactory/basepage.py", line 124, in find_element
    return self.driver.find_element(self.locationTypeDict[location_type.lower()], locator_expression)
  File "/Users/liushiwen/.local/lib/python3.8/site-packages/selenium/webdriver/remote/webdriver.py", line 976, in find_element
    return self.execute(Command.FIND_ELEMENT, {
  File "/Users/liushiwen/.local/lib/python3.8/site-packages/selenium/webdriver/remote/webdriver.py", line 321, in execute
    self.error_handler.check_response(response)
  File "/Users/liushiwen/.local/lib/python3.8/site-packages/selenium/webdriver/remote/errorhandler.py", line 242, in check_response
    raise exception_class(message, screen, stacktrace)
selenium.common.exceptions.WebDriverException: Message: chrome not reachable
  (Session info: chrome=91.0.4472.164)


2021-07-21 11:35:23,881 : accordingWait.py : ERROR : Traceback (most recent call last):
  File "/Users/liushiwen/PycharmProjects/MyTestFramwoek/Common/accordingWait.py", line 82, in presence_of_element_located
    self._wait.until(
  File "/Users/liushiwen/.local/lib/python3.8/site-packages/selenium/webdriver/support/wait.py", line 71, in until
    value = method(self._driver)
  File "/Users/liushiwen/.local/lib/python3.8/site-packages/selenium/webdriver/support/expected_conditions.py", line 64, in __call__
    return _find_element(driver, self.locator)
  File "/Users/liushiwen/.local/lib/python3.8/site-packages/selenium/webdriver/support/expected_conditions.py", line 415, in _find_element
    raise e
  File "/Users/liushiwen/.local/lib/python3.8/site-packages/selenium/webdriver/support/expected_conditions.py", line 411, in _find_element
    return driver.find_element(*by)
  File "/Users/liushiwen/.local/lib/python3.8/site-packages/selenium/webdriver/remote/webdriver.py", line 976, in find_element
    return self.execute(Command.FIND_ELEMENT, {
  File "/Users/liushiwen/.local/lib/python3.8/site-packages/selenium/webdriver/remote/webdriver.py", line 321, in execute
    self.error_handler.check_response(response)
  File "/Users/liushiwen/.local/lib/python3.8/site-packages/selenium/webdriver/remote/errorhandler.py", line 242, in check_response
    raise exception_class(message, screen, stacktrace)
selenium.common.exceptions.NoSuchWindowException: Message: no such window: window was already closed
  (Session info: chrome=91.0.4472.164)


2021-07-21 11:35:23,881 : accordingWait.py : ERROR : Traceback (most recent call last):
  File "/Users/liushiwen/PycharmProjects/MyTestFramwoek/Common/accordingWait.py", line 82, in presence_of_element_located
    self._wait.until(
  File "/Users/liushiwen/.local/lib/python3.8/site-packages/selenium/webdriver/support/wait.py", line 71, in until
    value = method(self._driver)
  File "/Users/liushiwen/.local/lib/python3.8/site-packages/selenium/webdriver/support/expected_conditions.py", line 64, in __call__
    return _find_element(driver, self.locator)
  File "/Users/liushiwen/.local/lib/python3.8/site-packages/selenium/webdriver/support/expected_conditions.py", line 415, in _find_element
    raise e
  File "/Users/liushiwen/.local/lib/python3.8/site-packages/selenium/webdriver/support/expected_conditions.py", line 411, in _find_element
    return driver.find_element(*by)
  File "/Users/liushiwen/.local/lib/python3.8/site-packages/selenium/webdriver/remote/webdriver.py", line 976, in find_element
    return self.execute(Command.FIND_ELEMENT, {
  File "/Users/liushiwen/.local/lib/python3.8/site-packages/selenium/webdriver/remote/webdriver.py", line 321, in execute
    self.error_handler.check_response(response)
  File "/Users/liushiwen/.local/lib/python3.8/site-packages/selenium/webdriver/remote/errorhandler.py", line 242, in check_response
    raise exception_class(message, screen, stacktrace)
selenium.common.exceptions.NoSuchWindowException: Message: no such window: window was already closed
  (Session info: chrome=91.0.4472.164)


2021-07-21 11:35:23,895 : basepage.py : ERROR : 请检查定位方式和定位表达式格式是否正确
2021-07-21 11:35:23,895 : basepage.py : ERROR : 请检查定位方式和定位表达式格式是否正确
2021-07-21 11:35:23,897 : basepage.py : ERROR : Traceback (most recent call last):
  File "/Users/liushiwen/PycharmProjects/MyTestFramwoek/UITestObjects/BaseFactory/basepage.py", line 124, in find_element
    return self.driver.find_element(self.locationTypeDict[location_type.lower()], locator_expression)
  File "/Users/liushiwen/.local/lib/python3.8/site-packages/selenium/webdriver/remote/webdriver.py", line 976, in find_element
    return self.execute(Command.FIND_ELEMENT, {
  File "/Users/liushiwen/.local/lib/python3.8/site-packages/selenium/webdriver/remote/webdriver.py", line 321, in execute
    self.error_handler.check_response(response)
  File "/Users/liushiwen/.local/lib/python3.8/site-packages/selenium/webdriver/remote/errorhandler.py", line 242, in check_response
    raise exception_class(message, screen, stacktrace)
selenium.common.exceptions.NoSuchWindowException: Message: no such window: window was already closed
  (Session info: chrome=91.0.4472.164)


2021-07-21 11:35:23,897 : basepage.py : ERROR : Traceback (most recent call last):
  File "/Users/liushiwen/PycharmProjects/MyTestFramwoek/UITestObjects/BaseFactory/basepage.py", line 124, in find_element
    return self.driver.find_element(self.locationTypeDict[location_type.lower()], locator_expression)
  File "/Users/liushiwen/.local/lib/python3.8/site-packages/selenium/webdriver/remote/webdriver.py", line 976, in find_element
    return self.execute(Command.FIND_ELEMENT, {
  File "/Users/liushiwen/.local/lib/python3.8/site-packages/selenium/webdriver/remote/webdriver.py", line 321, in execute
    self.error_handler.check_response(response)
  File "/Users/liushiwen/.local/lib/python3.8/site-packages/selenium/webdriver/remote/errorhandler.py", line 242, in check_response
    raise exception_class(message, screen, stacktrace)
selenium.common.exceptions.NoSuchWindowException: Message: no such window: window was already closed
  (Session info: chrome=91.0.4472.164)


2021-07-21 11:36:33,201 : accordingWait.py : ERROR : Traceback (most recent call last):
  File "/Users/liushiwen/PycharmProjects/MyTestFramwoek/Common/accordingWait.py", line 82, in presence_of_element_located
    self._wait.until(
  File "/Users/liushiwen/.local/lib/python3.8/site-packages/selenium/webdriver/support/wait.py", line 71, in until
    value = method(self._driver)
  File "/Users/liushiwen/.local/lib/python3.8/site-packages/selenium/webdriver/support/expected_conditions.py", line 64, in __call__
    return _find_element(driver, self.locator)
  File "/Users/liushiwen/.local/lib/python3.8/site-packages/selenium/webdriver/support/expected_conditions.py", line 411, in _find_element
    return driver.find_element(*by)
  File "/Users/liushiwen/.local/lib/python3.8/site-packages/selenium/webdriver/remote/webdriver.py", line 976, in find_element
    return self.execute(Command.FIND_ELEMENT, {
  File "/Users/liushiwen/.local/lib/python3.8/site-packages/selenium/webdriver/remote/webdriver.py", line 319, in execute
    response = self.command_executor.execute(driver_command, params)
  File "/Users/liushiwen/.local/lib/python3.8/site-packages/selenium/webdriver/remote/remote_connection.py", line 374, in execute
    return self._request(command_info[0], url, body=data)
  File "/Users/liushiwen/.local/lib/python3.8/site-packages/selenium/webdriver/remote/remote_connection.py", line 397, in _request
    resp = self._conn.request(method, url, body=body, headers=headers)
  File "/Users/liushiwen/.local/lib/python3.8/site-packages/urllib3/request.py", line 78, in request
    return self.request_encode_body(
  File "/Users/liushiwen/.local/lib/python3.8/site-packages/urllib3/request.py", line 170, in request_encode_body
    return self.urlopen(method, url, **extra_kw)
  File "/Users/liushiwen/.local/lib/python3.8/site-packages/urllib3/poolmanager.py", line 375, in urlopen
    response = conn.urlopen(method, u.request_uri, **kw)
  File "/Users/liushiwen/.local/lib/python3.8/site-packages/urllib3/connectionpool.py", line 699, in urlopen
    httplib_response = self._make_request(
  File "/Users/liushiwen/.local/lib/python3.8/site-packages/urllib3/connectionpool.py", line 445, in _make_request
    six.raise_from(e, None)
  File "<string>", line 3, in raise_from
  File "/Users/liushiwen/.local/lib/python3.8/site-packages/urllib3/connectionpool.py", line 440, in _make_request
    httplib_response = conn.getresponse()
  File "/Users/liushiwen/miniforge3/envs/py38/lib/python3.8/http/client.py", line 1344, in getresponse
    response.begin()
  File "/Users/liushiwen/miniforge3/envs/py38/lib/python3.8/http/client.py", line 307, in begin
    version, status, reason = self._read_status()
  File "/Users/liushiwen/miniforge3/envs/py38/lib/python3.8/http/client.py", line 268, in _read_status
    line = str(self.fp.readline(_MAXLINE + 1), "iso-8859-1")
  File "/Users/liushiwen/miniforge3/envs/py38/lib/python3.8/socket.py", line 669, in readinto
    return self._sock.recv_into(b)
KeyboardInterrupt

2021-07-21 11:36:33,201 : accordingWait.py : ERROR : Traceback (most recent call last):
  File "/Users/liushiwen/PycharmProjects/MyTestFramwoek/Common/accordingWait.py", line 82, in presence_of_element_located
    self._wait.until(
  File "/Users/liushiwen/.local/lib/python3.8/site-packages/selenium/webdriver/support/wait.py", line 71, in until
    value = method(self._driver)
  File "/Users/liushiwen/.local/lib/python3.8/site-packages/selenium/webdriver/support/expected_conditions.py", line 64, in __call__
    return _find_element(driver, self.locator)
  File "/Users/liushiwen/.local/lib/python3.8/site-packages/selenium/webdriver/support/expected_conditions.py", line 411, in _find_element
    return driver.find_element(*by)
  File "/Users/liushiwen/.local/lib/python3.8/site-packages/selenium/webdriver/remote/webdriver.py", line 976, in find_element
    return self.execute(Command.FIND_ELEMENT, {
  File "/Users/liushiwen/.local/lib/python3.8/site-packages/selenium/webdriver/remote/webdriver.py", line 319, in execute
    response = self.command_executor.execute(driver_command, params)
  File "/Users/liushiwen/.local/lib/python3.8/site-packages/selenium/webdriver/remote/remote_connection.py", line 374, in execute
    return self._request(command_info[0], url, body=data)
  File "/Users/liushiwen/.local/lib/python3.8/site-packages/selenium/webdriver/remote/remote_connection.py", line 397, in _request
    resp = self._conn.request(method, url, body=body, headers=headers)
  File "/Users/liushiwen/.local/lib/python3.8/site-packages/urllib3/request.py", line 78, in request
    return self.request_encode_body(
  File "/Users/liushiwen/.local/lib/python3.8/site-packages/urllib3/request.py", line 170, in request_encode_body
    return self.urlopen(method, url, **extra_kw)
  File "/Users/liushiwen/.local/lib/python3.8/site-packages/urllib3/poolmanager.py", line 375, in urlopen
    response = conn.urlopen(method, u.request_uri, **kw)
  File "/Users/liushiwen/.local/lib/python3.8/site-packages/urllib3/connectionpool.py", line 699, in urlopen
    httplib_response = self._make_request(
  File "/Users/liushiwen/.local/lib/python3.8/site-packages/urllib3/connectionpool.py", line 445, in _make_request
    six.raise_from(e, None)
  File "<string>", line 3, in raise_from
  File "/Users/liushiwen/.local/lib/python3.8/site-packages/urllib3/connectionpool.py", line 440, in _make_request
    httplib_response = conn.getresponse()
  File "/Users/liushiwen/miniforge3/envs/py38/lib/python3.8/http/client.py", line 1344, in getresponse
    response.begin()
  File "/Users/liushiwen/miniforge3/envs/py38/lib/python3.8/http/client.py", line 307, in begin
    version, status, reason = self._read_status()
  File "/Users/liushiwen/miniforge3/envs/py38/lib/python3.8/http/client.py", line 268, in _read_status
    line = str(self.fp.readline(_MAXLINE + 1), "iso-8859-1")
  File "/Users/liushiwen/miniforge3/envs/py38/lib/python3.8/socket.py", line 669, in readinto
    return self._sock.recv_into(b)
KeyboardInterrupt

2021-07-21 11:36:33,202 : basepage.py : ERROR : 请检查定位方式和定位表达式格式是否正确
2021-07-21 11:36:33,202 : basepage.py : ERROR : 请检查定位方式和定位表达式格式是否正确
2021-07-21 11:36:33,203 : basepage.py : ERROR : Traceback (most recent call last):
  File "/Users/liushiwen/.local/lib/python3.8/site-packages/urllib3/connection.py", line 169, in _new_conn
    conn = connection.create_connection(
  File "/Users/liushiwen/.local/lib/python3.8/site-packages/urllib3/util/connection.py", line 96, in create_connection
    raise err
  File "/Users/liushiwen/.local/lib/python3.8/site-packages/urllib3/util/connection.py", line 86, in create_connection
    sock.connect(sa)
ConnectionRefusedError: [Errno 61] Connection refused

During handling of the above exception, another exception occurred:

Traceback (most recent call last):
  File "/Users/liushiwen/.local/lib/python3.8/site-packages/urllib3/connectionpool.py", line 699, in urlopen
    httplib_response = self._make_request(
  File "/Users/liushiwen/.local/lib/python3.8/site-packages/urllib3/connectionpool.py", line 394, in _make_request
    conn.request(method, url, **httplib_request_kw)
  File "/Users/liushiwen/.local/lib/python3.8/site-packages/urllib3/connection.py", line 234, in request
    super(HTTPConnection, self).request(method, url, body=body, headers=headers)
  File "/Users/liushiwen/miniforge3/envs/py38/lib/python3.8/http/client.py", line 1252, in request
    self._send_request(method, url, body, headers, encode_chunked)
  File "/Users/liushiwen/miniforge3/envs/py38/lib/python3.8/http/client.py", line 1298, in _send_request
    self.endheaders(body, encode_chunked=encode_chunked)
  File "/Users/liushiwen/miniforge3/envs/py38/lib/python3.8/http/client.py", line 1247, in endheaders
    self._send_output(message_body, encode_chunked=encode_chunked)
  File "/Users/liushiwen/miniforge3/envs/py38/lib/python3.8/http/client.py", line 1007, in _send_output
    self.send(msg)
  File "/Users/liushiwen/miniforge3/envs/py38/lib/python3.8/http/client.py", line 947, in send
    self.connect()
  File "/Users/liushiwen/.local/lib/python3.8/site-packages/urllib3/connection.py", line 200, in connect
    conn = self._new_conn()
  File "/Users/liushiwen/.local/lib/python3.8/site-packages/urllib3/connection.py", line 181, in _new_conn
    raise NewConnectionError(
urllib3.exceptions.NewConnectionError: <urllib3.connection.HTTPConnection object at 0x1211173a0>: Failed to establish a new connection: [Errno 61] Connection refused

During handling of the above exception, another exception occurred:

Traceback (most recent call last):
  File "/Users/liushiwen/PycharmProjects/MyTestFramwoek/UITestObjects/BaseFactory/basepage.py", line 124, in find_element
    return self.driver.find_element(self.locationTypeDict[location_type.lower()], locator_expression)
  File "/Users/liushiwen/.local/lib/python3.8/site-packages/selenium/webdriver/remote/webdriver.py", line 976, in find_element
    return self.execute(Command.FIND_ELEMENT, {
  File "/Users/liushiwen/.local/lib/python3.8/site-packages/selenium/webdriver/remote/webdriver.py", line 319, in execute
    response = self.command_executor.execute(driver_command, params)
  File "/Users/liushiwen/.local/lib/python3.8/site-packages/selenium/webdriver/remote/remote_connection.py", line 374, in execute
    return self._request(command_info[0], url, body=data)
  File "/Users/liushiwen/.local/lib/python3.8/site-packages/selenium/webdriver/remote/remote_connection.py", line 397, in _request
    resp = self._conn.request(method, url, body=body, headers=headers)
  File "/Users/liushiwen/.local/lib/python3.8/site-packages/urllib3/request.py", line 78, in request
    return self.request_encode_body(
  File "/Users/liushiwen/.local/lib/python3.8/site-packages/urllib3/request.py", line 170, in request_encode_body
    return self.urlopen(method, url, **extra_kw)
  File "/Users/liushiwen/.local/lib/python3.8/site-packages/urllib3/poolmanager.py", line 375, in urlopen
    response = conn.urlopen(method, u.request_uri, **kw)
  File "/Users/liushiwen/.local/lib/python3.8/site-packages/urllib3/connectionpool.py", line 783, in urlopen
    return self.urlopen(
  File "/Users/liushiwen/.local/lib/python3.8/site-packages/urllib3/connectionpool.py", line 783, in urlopen
    return self.urlopen(
  File "/Users/liushiwen/.local/lib/python3.8/site-packages/urllib3/connectionpool.py", line 783, in urlopen
    return self.urlopen(
  File "/Users/liushiwen/.local/lib/python3.8/site-packages/urllib3/connectionpool.py", line 755, in urlopen
    retries = retries.increment(
  File "/Users/liushiwen/.local/lib/python3.8/site-packages/urllib3/util/retry.py", line 574, in increment
    raise MaxRetryError(_pool, url, error or ResponseError(cause))
urllib3.exceptions.MaxRetryError: HTTPConnectionPool(host='127.0.0.1', port=60743): Max retries exceeded with url: /session/f7c340267f9db153b52513943a5e7fd1/element (Caused by NewConnectionError('<urllib3.connection.HTTPConnection object at 0x1211173a0>: Failed to establish a new connection: [Errno 61] Connection refused'))

2021-07-21 11:36:33,203 : basepage.py : ERROR : Traceback (most recent call last):
  File "/Users/liushiwen/.local/lib/python3.8/site-packages/urllib3/connection.py", line 169, in _new_conn
    conn = connection.create_connection(
  File "/Users/liushiwen/.local/lib/python3.8/site-packages/urllib3/util/connection.py", line 96, in create_connection
    raise err
  File "/Users/liushiwen/.local/lib/python3.8/site-packages/urllib3/util/connection.py", line 86, in create_connection
    sock.connect(sa)
ConnectionRefusedError: [Errno 61] Connection refused

During handling of the above exception, another exception occurred:

Traceback (most recent call last):
  File "/Users/liushiwen/.local/lib/python3.8/site-packages/urllib3/connectionpool.py", line 699, in urlopen
    httplib_response = self._make_request(
  File "/Users/liushiwen/.local/lib/python3.8/site-packages/urllib3/connectionpool.py", line 394, in _make_request
    conn.request(method, url, **httplib_request_kw)
  File "/Users/liushiwen/.local/lib/python3.8/site-packages/urllib3/connection.py", line 234, in request
    super(HTTPConnection, self).request(method, url, body=body, headers=headers)
  File "/Users/liushiwen/miniforge3/envs/py38/lib/python3.8/http/client.py", line 1252, in request
    self._send_request(method, url, body, headers, encode_chunked)
  File "/Users/liushiwen/miniforge3/envs/py38/lib/python3.8/http/client.py", line 1298, in _send_request
    self.endheaders(body, encode_chunked=encode_chunked)
  File "/Users/liushiwen/miniforge3/envs/py38/lib/python3.8/http/client.py", line 1247, in endheaders
    self._send_output(message_body, encode_chunked=encode_chunked)
  File "/Users/liushiwen/miniforge3/envs/py38/lib/python3.8/http/client.py", line 1007, in _send_output
    self.send(msg)
  File "/Users/liushiwen/miniforge3/envs/py38/lib/python3.8/http/client.py", line 947, in send
    self.connect()
  File "/Users/liushiwen/.local/lib/python3.8/site-packages/urllib3/connection.py", line 200, in connect
    conn = self._new_conn()
  File "/Users/liushiwen/.local/lib/python3.8/site-packages/urllib3/connection.py", line 181, in _new_conn
    raise NewConnectionError(
urllib3.exceptions.NewConnectionError: <urllib3.connection.HTTPConnection object at 0x1211173a0>: Failed to establish a new connection: [Errno 61] Connection refused

During handling of the above exception, another exception occurred:

Traceback (most recent call last):
  File "/Users/liushiwen/PycharmProjects/MyTestFramwoek/UITestObjects/BaseFactory/basepage.py", line 124, in find_element
    return self.driver.find_element(self.locationTypeDict[location_type.lower()], locator_expression)
  File "/Users/liushiwen/.local/lib/python3.8/site-packages/selenium/webdriver/remote/webdriver.py", line 976, in find_element
    return self.execute(Command.FIND_ELEMENT, {
  File "/Users/liushiwen/.local/lib/python3.8/site-packages/selenium/webdriver/remote/webdriver.py", line 319, in execute
    response = self.command_executor.execute(driver_command, params)
  File "/Users/liushiwen/.local/lib/python3.8/site-packages/selenium/webdriver/remote/remote_connection.py", line 374, in execute
    return self._request(command_info[0], url, body=data)
  File "/Users/liushiwen/.local/lib/python3.8/site-packages/selenium/webdriver/remote/remote_connection.py", line 397, in _request
    resp = self._conn.request(method, url, body=body, headers=headers)
  File "/Users/liushiwen/.local/lib/python3.8/site-packages/urllib3/request.py", line 78, in request
    return self.request_encode_body(
  File "/Users/liushiwen/.local/lib/python3.8/site-packages/urllib3/request.py", line 170, in request_encode_body
    return self.urlopen(method, url, **extra_kw)
  File "/Users/liushiwen/.local/lib/python3.8/site-packages/urllib3/poolmanager.py", line 375, in urlopen
    response = conn.urlopen(method, u.request_uri, **kw)
  File "/Users/liushiwen/.local/lib/python3.8/site-packages/urllib3/connectionpool.py", line 783, in urlopen
    return self.urlopen(
  File "/Users/liushiwen/.local/lib/python3.8/site-packages/urllib3/connectionpool.py", line 783, in urlopen
    return self.urlopen(
  File "/Users/liushiwen/.local/lib/python3.8/site-packages/urllib3/connectionpool.py", line 783, in urlopen
    return self.urlopen(
  File "/Users/liushiwen/.local/lib/python3.8/site-packages/urllib3/connectionpool.py", line 755, in urlopen
    retries = retries.increment(
  File "/Users/liushiwen/.local/lib/python3.8/site-packages/urllib3/util/retry.py", line 574, in increment
    raise MaxRetryError(_pool, url, error or ResponseError(cause))
urllib3.exceptions.MaxRetryError: HTTPConnectionPool(host='127.0.0.1', port=60743): Max retries exceeded with url: /session/f7c340267f9db153b52513943a5e7fd1/element (Caused by NewConnectionError('<urllib3.connection.HTTPConnection object at 0x1211173a0>: Failed to establish a new connection: [Errno 61] Connection refused'))

2021-07-21 14:15:20,237 : testUserLogin.py : ERROR : Traceback (most recent call last):
  File "/Users/liushiwen/PycharmProjects/MyTestFramwoek/TestCases/UITestCases/testUserLogin.py", line 26, in test_login
    assert alert_text == "用户名不正确。"
AssertionError: assert '验证码不正确' == '用户名不正确。'
  - 用户名不正确。
  + 验证码不正确

2021-07-21 14:15:20,237 : testUserLogin.py : ERROR : Traceback (most recent call last):
  File "/Users/liushiwen/PycharmProjects/MyTestFramwoek/TestCases/UITestCases/testUserLogin.py", line 26, in test_login
    assert alert_text == "用户名不正确。"
AssertionError: assert '验证码不正确' == '用户名不正确。'
  - 用户名不正确。
  + 验证码不正确

2021-07-21 14:15:20,237 : testUserLogin.py : ERROR : Traceback (most recent call last):
  File "/Users/liushiwen/PycharmProjects/MyTestFramwoek/TestCases/UITestCases/testUserLogin.py", line 26, in test_login
    assert alert_text == "用户名不正确。"
AssertionError: assert '验证码不正确' == '用户名不正确。'
  - 用户名不正确。
  + 验证码不正确

2021-07-21 14:15:20,237 : testUserLogin.py : ERROR : Traceback (most recent call last):
  File "/Users/liushiwen/PycharmProjects/MyTestFramwoek/TestCases/UITestCases/testUserLogin.py", line 26, in test_login
    assert alert_text == "用户名不正确。"
AssertionError: assert '验证码不正确' == '用户名不正确。'
  - 用户名不正确。
  + 验证码不正确

2021-07-21 14:15:20,237 : testUserLogin.py : ERROR : Traceback (most recent call last):
  File "/Users/liushiwen/PycharmProjects/MyTestFramwoek/TestCases/UITestCases/testUserLogin.py", line 26, in test_login
    assert alert_text == "用户名不正确。"
AssertionError: assert '验证码不正确' == '用户名不正确。'
  - 用户名不正确。
  + 验证码不正确

2021-07-21 14:15:20,237 : testUserLogin.py : ERROR : Traceback (most recent call last):
  File "/Users/liushiwen/PycharmProjects/MyTestFramwoek/TestCases/UITestCases/testUserLogin.py", line 26, in test_login
    assert alert_text == "用户名不正确。"
AssertionError: assert '验证码不正确' == '用户名不正确。'
  - 用户名不正确。
  + 验证码不正确

2021-07-21 14:15:20,237 : testUserLogin.py : ERROR : Traceback (most recent call last):
  File "/Users/liushiwen/PycharmProjects/MyTestFramwoek/TestCases/UITestCases/testUserLogin.py", line 26, in test_login
    assert alert_text == "用户名不正确。"
AssertionError: assert '验证码不正确' == '用户名不正确。'
  - 用户名不正确。
  + 验证码不正确

2021-07-21 14:15:20,237 : testUserLogin.py : ERROR : Traceback (most recent call last):
  File "/Users/liushiwen/PycharmProjects/MyTestFramwoek/TestCases/UITestCases/testUserLogin.py", line 26, in test_login
    assert alert_text == "用户名不正确。"
AssertionError: assert '验证码不正确' == '用户名不正确。'
  - 用户名不正确。
  + 验证码不正确

2021-07-21 14:15:20,237 : testUserLogin.py : ERROR : Traceback (most recent call last):
  File "/Users/liushiwen/PycharmProjects/MyTestFramwoek/TestCases/UITestCases/testUserLogin.py", line 26, in test_login
    assert alert_text == "用户名不正确。"
AssertionError: assert '验证码不正确' == '用户名不正确。'
  - 用户名不正确。
  + 验证码不正确

2021-07-21 14:15:20,237 : testUserLogin.py : ERROR : Traceback (most recent call last):
  File "/Users/liushiwen/PycharmProjects/MyTestFramwoek/TestCases/UITestCases/testUserLogin.py", line 26, in test_login
    assert alert_text == "用户名不正确。"
AssertionError: assert '验证码不正确' == '用户名不正确。'
  - 用户名不正确。
  + 验证码不正确

2021-07-21 14:15:33,320 : testUserLogin.py : ERROR : Traceback (most recent call last):
  File "/Users/liushiwen/PycharmProjects/MyTestFramwoek/TestCases/UITestCases/testUserLogin.py", line 25, in test_login
    alert_text = self.login.get_alert_text()
  File "/Users/liushiwen/PycharmProjects/MyTestFramwoek/UITestObjects/BaseFactory/basepage.py", line 512, in get_alert_text
    return self.driver.switch_to.alert.text
  File "/Users/liushiwen/.local/lib/python3.8/site-packages/selenium/webdriver/remote/switch_to.py", line 55, in alert
    alert.text
  File "/Users/liushiwen/.local/lib/python3.8/site-packages/selenium/webdriver/common/alert.py", line 67, in text
    return self.driver.execute(Command.W3C_GET_ALERT_TEXT)["value"]
  File "/Users/liushiwen/.local/lib/python3.8/site-packages/selenium/webdriver/remote/webdriver.py", line 321, in execute
    self.error_handler.check_response(response)
  File "/Users/liushiwen/.local/lib/python3.8/site-packages/selenium/webdriver/remote/errorhandler.py", line 242, in check_response
    raise exception_class(message, screen, stacktrace)
selenium.common.exceptions.NoAlertPresentException: Message: no such alert
  (Session info: chrome=91.0.4472.164)


2021-07-21 14:15:33,320 : testUserLogin.py : ERROR : Traceback (most recent call last):
  File "/Users/liushiwen/PycharmProjects/MyTestFramwoek/TestCases/UITestCases/testUserLogin.py", line 25, in test_login
    alert_text = self.login.get_alert_text()
  File "/Users/liushiwen/PycharmProjects/MyTestFramwoek/UITestObjects/BaseFactory/basepage.py", line 512, in get_alert_text
    return self.driver.switch_to.alert.text
  File "/Users/liushiwen/.local/lib/python3.8/site-packages/selenium/webdriver/remote/switch_to.py", line 55, in alert
    alert.text
  File "/Users/liushiwen/.local/lib/python3.8/site-packages/selenium/webdriver/common/alert.py", line 67, in text
    return self.driver.execute(Command.W3C_GET_ALERT_TEXT)["value"]
  File "/Users/liushiwen/.local/lib/python3.8/site-packages/selenium/webdriver/remote/webdriver.py", line 321, in execute
    self.error_handler.check_response(response)
  File "/Users/liushiwen/.local/lib/python3.8/site-packages/selenium/webdriver/remote/errorhandler.py", line 242, in check_response
    raise exception_class(message, screen, stacktrace)
selenium.common.exceptions.NoAlertPresentException: Message: no such alert
  (Session info: chrome=91.0.4472.164)


2021-07-21 14:15:33,320 : testUserLogin.py : ERROR : Traceback (most recent call last):
  File "/Users/liushiwen/PycharmProjects/MyTestFramwoek/TestCases/UITestCases/testUserLogin.py", line 25, in test_login
    alert_text = self.login.get_alert_text()
  File "/Users/liushiwen/PycharmProjects/MyTestFramwoek/UITestObjects/BaseFactory/basepage.py", line 512, in get_alert_text
    return self.driver.switch_to.alert.text
  File "/Users/liushiwen/.local/lib/python3.8/site-packages/selenium/webdriver/remote/switch_to.py", line 55, in alert
    alert.text
  File "/Users/liushiwen/.local/lib/python3.8/site-packages/selenium/webdriver/common/alert.py", line 67, in text
    return self.driver.execute(Command.W3C_GET_ALERT_TEXT)["value"]
  File "/Users/liushiwen/.local/lib/python3.8/site-packages/selenium/webdriver/remote/webdriver.py", line 321, in execute
    self.error_handler.check_response(response)
  File "/Users/liushiwen/.local/lib/python3.8/site-packages/selenium/webdriver/remote/errorhandler.py", line 242, in check_response
    raise exception_class(message, screen, stacktrace)
selenium.common.exceptions.NoAlertPresentException: Message: no such alert
  (Session info: chrome=91.0.4472.164)


2021-07-21 14:15:33,320 : testUserLogin.py : ERROR : Traceback (most recent call last):
  File "/Users/liushiwen/PycharmProjects/MyTestFramwoek/TestCases/UITestCases/testUserLogin.py", line 25, in test_login
    alert_text = self.login.get_alert_text()
  File "/Users/liushiwen/PycharmProjects/MyTestFramwoek/UITestObjects/BaseFactory/basepage.py", line 512, in get_alert_text
    return self.driver.switch_to.alert.text
  File "/Users/liushiwen/.local/lib/python3.8/site-packages/selenium/webdriver/remote/switch_to.py", line 55, in alert
    alert.text
  File "/Users/liushiwen/.local/lib/python3.8/site-packages/selenium/webdriver/common/alert.py", line 67, in text
    return self.driver.execute(Command.W3C_GET_ALERT_TEXT)["value"]
  File "/Users/liushiwen/.local/lib/python3.8/site-packages/selenium/webdriver/remote/webdriver.py", line 321, in execute
    self.error_handler.check_response(response)
  File "/Users/liushiwen/.local/lib/python3.8/site-packages/selenium/webdriver/remote/errorhandler.py", line 242, in check_response
    raise exception_class(message, screen, stacktrace)
selenium.common.exceptions.NoAlertPresentException: Message: no such alert
  (Session info: chrome=91.0.4472.164)


2021-07-21 14:15:33,320 : testUserLogin.py : ERROR : Traceback (most recent call last):
  File "/Users/liushiwen/PycharmProjects/MyTestFramwoek/TestCases/UITestCases/testUserLogin.py", line 25, in test_login
    alert_text = self.login.get_alert_text()
  File "/Users/liushiwen/PycharmProjects/MyTestFramwoek/UITestObjects/BaseFactory/basepage.py", line 512, in get_alert_text
    return self.driver.switch_to.alert.text
  File "/Users/liushiwen/.local/lib/python3.8/site-packages/selenium/webdriver/remote/switch_to.py", line 55, in alert
    alert.text
  File "/Users/liushiwen/.local/lib/python3.8/site-packages/selenium/webdriver/common/alert.py", line 67, in text
    return self.driver.execute(Command.W3C_GET_ALERT_TEXT)["value"]
  File "/Users/liushiwen/.local/lib/python3.8/site-packages/selenium/webdriver/remote/webdriver.py", line 321, in execute
    self.error_handler.check_response(response)
  File "/Users/liushiwen/.local/lib/python3.8/site-packages/selenium/webdriver/remote/errorhandler.py", line 242, in check_response
    raise exception_class(message, screen, stacktrace)
selenium.common.exceptions.NoAlertPresentException: Message: no such alert
  (Session info: chrome=91.0.4472.164)


2021-07-21 14:15:33,320 : testUserLogin.py : ERROR : Traceback (most recent call last):
  File "/Users/liushiwen/PycharmProjects/MyTestFramwoek/TestCases/UITestCases/testUserLogin.py", line 25, in test_login
    alert_text = self.login.get_alert_text()
  File "/Users/liushiwen/PycharmProjects/MyTestFramwoek/UITestObjects/BaseFactory/basepage.py", line 512, in get_alert_text
    return self.driver.switch_to.alert.text
  File "/Users/liushiwen/.local/lib/python3.8/site-packages/selenium/webdriver/remote/switch_to.py", line 55, in alert
    alert.text
  File "/Users/liushiwen/.local/lib/python3.8/site-packages/selenium/webdriver/common/alert.py", line 67, in text
    return self.driver.execute(Command.W3C_GET_ALERT_TEXT)["value"]
  File "/Users/liushiwen/.local/lib/python3.8/site-packages/selenium/webdriver/remote/webdriver.py", line 321, in execute
    self.error_handler.check_response(response)
  File "/Users/liushiwen/.local/lib/python3.8/site-packages/selenium/webdriver/remote/errorhandler.py", line 242, in check_response
    raise exception_class(message, screen, stacktrace)
selenium.common.exceptions.NoAlertPresentException: Message: no such alert
  (Session info: chrome=91.0.4472.164)


2021-07-21 14:15:33,320 : testUserLogin.py : ERROR : Traceback (most recent call last):
  File "/Users/liushiwen/PycharmProjects/MyTestFramwoek/TestCases/UITestCases/testUserLogin.py", line 25, in test_login
    alert_text = self.login.get_alert_text()
  File "/Users/liushiwen/PycharmProjects/MyTestFramwoek/UITestObjects/BaseFactory/basepage.py", line 512, in get_alert_text
    return self.driver.switch_to.alert.text
  File "/Users/liushiwen/.local/lib/python3.8/site-packages/selenium/webdriver/remote/switch_to.py", line 55, in alert
    alert.text
  File "/Users/liushiwen/.local/lib/python3.8/site-packages/selenium/webdriver/common/alert.py", line 67, in text
    return self.driver.execute(Command.W3C_GET_ALERT_TEXT)["value"]
  File "/Users/liushiwen/.local/lib/python3.8/site-packages/selenium/webdriver/remote/webdriver.py", line 321, in execute
    self.error_handler.check_response(response)
  File "/Users/liushiwen/.local/lib/python3.8/site-packages/selenium/webdriver/remote/errorhandler.py", line 242, in check_response
    raise exception_class(message, screen, stacktrace)
selenium.common.exceptions.NoAlertPresentException: Message: no such alert
  (Session info: chrome=91.0.4472.164)


2021-07-21 14:15:33,320 : testUserLogin.py : ERROR : Traceback (most recent call last):
  File "/Users/liushiwen/PycharmProjects/MyTestFramwoek/TestCases/UITestCases/testUserLogin.py", line 25, in test_login
    alert_text = self.login.get_alert_text()
  File "/Users/liushiwen/PycharmProjects/MyTestFramwoek/UITestObjects/BaseFactory/basepage.py", line 512, in get_alert_text
    return self.driver.switch_to.alert.text
  File "/Users/liushiwen/.local/lib/python3.8/site-packages/selenium/webdriver/remote/switch_to.py", line 55, in alert
    alert.text
  File "/Users/liushiwen/.local/lib/python3.8/site-packages/selenium/webdriver/common/alert.py", line 67, in text
    return self.driver.execute(Command.W3C_GET_ALERT_TEXT)["value"]
  File "/Users/liushiwen/.local/lib/python3.8/site-packages/selenium/webdriver/remote/webdriver.py", line 321, in execute
    self.error_handler.check_response(response)
  File "/Users/liushiwen/.local/lib/python3.8/site-packages/selenium/webdriver/remote/errorhandler.py", line 242, in check_response
    raise exception_class(message, screen, stacktrace)
selenium.common.exceptions.NoAlertPresentException: Message: no such alert
  (Session info: chrome=91.0.4472.164)


2021-07-21 14:15:33,320 : testUserLogin.py : ERROR : Traceback (most recent call last):
  File "/Users/liushiwen/PycharmProjects/MyTestFramwoek/TestCases/UITestCases/testUserLogin.py", line 25, in test_login
    alert_text = self.login.get_alert_text()
  File "/Users/liushiwen/PycharmProjects/MyTestFramwoek/UITestObjects/BaseFactory/basepage.py", line 512, in get_alert_text
    return self.driver.switch_to.alert.text
  File "/Users/liushiwen/.local/lib/python3.8/site-packages/selenium/webdriver/remote/switch_to.py", line 55, in alert
    alert.text
  File "/Users/liushiwen/.local/lib/python3.8/site-packages/selenium/webdriver/common/alert.py", line 67, in text
    return self.driver.execute(Command.W3C_GET_ALERT_TEXT)["value"]
  File "/Users/liushiwen/.local/lib/python3.8/site-packages/selenium/webdriver/remote/webdriver.py", line 321, in execute
    self.error_handler.check_response(response)
  File "/Users/liushiwen/.local/lib/python3.8/site-packages/selenium/webdriver/remote/errorhandler.py", line 242, in check_response
    raise exception_class(message, screen, stacktrace)
selenium.common.exceptions.NoAlertPresentException: Message: no such alert
  (Session info: chrome=91.0.4472.164)


2021-07-21 14:15:33,320 : testUserLogin.py : ERROR : Traceback (most recent call last):
  File "/Users/liushiwen/PycharmProjects/MyTestFramwoek/TestCases/UITestCases/testUserLogin.py", line 25, in test_login
    alert_text = self.login.get_alert_text()
  File "/Users/liushiwen/PycharmProjects/MyTestFramwoek/UITestObjects/BaseFactory/basepage.py", line 512, in get_alert_text
    return self.driver.switch_to.alert.text
  File "/Users/liushiwen/.local/lib/python3.8/site-packages/selenium/webdriver/remote/switch_to.py", line 55, in alert
    alert.text
  File "/Users/liushiwen/.local/lib/python3.8/site-packages/selenium/webdriver/common/alert.py", line 67, in text
    return self.driver.execute(Command.W3C_GET_ALERT_TEXT)["value"]
  File "/Users/liushiwen/.local/lib/python3.8/site-packages/selenium/webdriver/remote/webdriver.py", line 321, in execute
    self.error_handler.check_response(response)
  File "/Users/liushiwen/.local/lib/python3.8/site-packages/selenium/webdriver/remote/errorhandler.py", line 242, in check_response
    raise exception_class(message, screen, stacktrace)
selenium.common.exceptions.NoAlertPresentException: Message: no such alert
  (Session info: chrome=91.0.4472.164)


2021-07-21 14:16:54,235 : testUserLogin.py : ERROR : Traceback (most recent call last):
  File "/Users/liushiwen/PycharmProjects/MyTestFramwoek/TestCases/UITestCases/testUserLogin.py", line 24, in test_login
    alert_text = self.login.get_alert_text()
  File "/Users/liushiwen/PycharmProjects/MyTestFramwoek/UITestObjects/BaseFactory/basepage.py", line 512, in get_alert_text
    return self.driver.switch_to.alert.text
  File "/Users/liushiwen/.local/lib/python3.8/site-packages/selenium/webdriver/remote/switch_to.py", line 55, in alert
    alert.text
  File "/Users/liushiwen/.local/lib/python3.8/site-packages/selenium/webdriver/common/alert.py", line 67, in text
    return self.driver.execute(Command.W3C_GET_ALERT_TEXT)["value"]
  File "/Users/liushiwen/.local/lib/python3.8/site-packages/selenium/webdriver/remote/webdriver.py", line 321, in execute
    self.error_handler.check_response(response)
  File "/Users/liushiwen/.local/lib/python3.8/site-packages/selenium/webdriver/remote/errorhandler.py", line 242, in check_response
    raise exception_class(message, screen, stacktrace)
selenium.common.exceptions.NoAlertPresentException: Message: no such alert
  (Session info: chrome=91.0.4472.164)


2021-07-21 14:16:54,235 : testUserLogin.py : ERROR : Traceback (most recent call last):
  File "/Users/liushiwen/PycharmProjects/MyTestFramwoek/TestCases/UITestCases/testUserLogin.py", line 24, in test_login
    alert_text = self.login.get_alert_text()
  File "/Users/liushiwen/PycharmProjects/MyTestFramwoek/UITestObjects/BaseFactory/basepage.py", line 512, in get_alert_text
    return self.driver.switch_to.alert.text
  File "/Users/liushiwen/.local/lib/python3.8/site-packages/selenium/webdriver/remote/switch_to.py", line 55, in alert
    alert.text
  File "/Users/liushiwen/.local/lib/python3.8/site-packages/selenium/webdriver/common/alert.py", line 67, in text
    return self.driver.execute(Command.W3C_GET_ALERT_TEXT)["value"]
  File "/Users/liushiwen/.local/lib/python3.8/site-packages/selenium/webdriver/remote/webdriver.py", line 321, in execute
    self.error_handler.check_response(response)
  File "/Users/liushiwen/.local/lib/python3.8/site-packages/selenium/webdriver/remote/errorhandler.py", line 242, in check_response
    raise exception_class(message, screen, stacktrace)
selenium.common.exceptions.NoAlertPresentException: Message: no such alert
  (Session info: chrome=91.0.4472.164)


2021-07-21 14:16:54,235 : testUserLogin.py : ERROR : Traceback (most recent call last):
  File "/Users/liushiwen/PycharmProjects/MyTestFramwoek/TestCases/UITestCases/testUserLogin.py", line 24, in test_login
    alert_text = self.login.get_alert_text()
  File "/Users/liushiwen/PycharmProjects/MyTestFramwoek/UITestObjects/BaseFactory/basepage.py", line 512, in get_alert_text
    return self.driver.switch_to.alert.text
  File "/Users/liushiwen/.local/lib/python3.8/site-packages/selenium/webdriver/remote/switch_to.py", line 55, in alert
    alert.text
  File "/Users/liushiwen/.local/lib/python3.8/site-packages/selenium/webdriver/common/alert.py", line 67, in text
    return self.driver.execute(Command.W3C_GET_ALERT_TEXT)["value"]
  File "/Users/liushiwen/.local/lib/python3.8/site-packages/selenium/webdriver/remote/webdriver.py", line 321, in execute
    self.error_handler.check_response(response)
  File "/Users/liushiwen/.local/lib/python3.8/site-packages/selenium/webdriver/remote/errorhandler.py", line 242, in check_response
    raise exception_class(message, screen, stacktrace)
selenium.common.exceptions.NoAlertPresentException: Message: no such alert
  (Session info: chrome=91.0.4472.164)


2021-07-21 14:16:54,235 : testUserLogin.py : ERROR : Traceback (most recent call last):
  File "/Users/liushiwen/PycharmProjects/MyTestFramwoek/TestCases/UITestCases/testUserLogin.py", line 24, in test_login
    alert_text = self.login.get_alert_text()
  File "/Users/liushiwen/PycharmProjects/MyTestFramwoek/UITestObjects/BaseFactory/basepage.py", line 512, in get_alert_text
    return self.driver.switch_to.alert.text
  File "/Users/liushiwen/.local/lib/python3.8/site-packages/selenium/webdriver/remote/switch_to.py", line 55, in alert
    alert.text
  File "/Users/liushiwen/.local/lib/python3.8/site-packages/selenium/webdriver/common/alert.py", line 67, in text
    return self.driver.execute(Command.W3C_GET_ALERT_TEXT)["value"]
  File "/Users/liushiwen/.local/lib/python3.8/site-packages/selenium/webdriver/remote/webdriver.py", line 321, in execute
    self.error_handler.check_response(response)
  File "/Users/liushiwen/.local/lib/python3.8/site-packages/selenium/webdriver/remote/errorhandler.py", line 242, in check_response
    raise exception_class(message, screen, stacktrace)
selenium.common.exceptions.NoAlertPresentException: Message: no such alert
  (Session info: chrome=91.0.4472.164)


2021-07-21 14:16:54,235 : testUserLogin.py : ERROR : Traceback (most recent call last):
  File "/Users/liushiwen/PycharmProjects/MyTestFramwoek/TestCases/UITestCases/testUserLogin.py", line 24, in test_login
    alert_text = self.login.get_alert_text()
  File "/Users/liushiwen/PycharmProjects/MyTestFramwoek/UITestObjects/BaseFactory/basepage.py", line 512, in get_alert_text
    return self.driver.switch_to.alert.text
  File "/Users/liushiwen/.local/lib/python3.8/site-packages/selenium/webdriver/remote/switch_to.py", line 55, in alert
    alert.text
  File "/Users/liushiwen/.local/lib/python3.8/site-packages/selenium/webdriver/common/alert.py", line 67, in text
    return self.driver.execute(Command.W3C_GET_ALERT_TEXT)["value"]
  File "/Users/liushiwen/.local/lib/python3.8/site-packages/selenium/webdriver/remote/webdriver.py", line 321, in execute
    self.error_handler.check_response(response)
  File "/Users/liushiwen/.local/lib/python3.8/site-packages/selenium/webdriver/remote/errorhandler.py", line 242, in check_response
    raise exception_class(message, screen, stacktrace)
selenium.common.exceptions.NoAlertPresentException: Message: no such alert
  (Session info: chrome=91.0.4472.164)


2021-07-21 14:16:54,235 : testUserLogin.py : ERROR : Traceback (most recent call last):
  File "/Users/liushiwen/PycharmProjects/MyTestFramwoek/TestCases/UITestCases/testUserLogin.py", line 24, in test_login
    alert_text = self.login.get_alert_text()
  File "/Users/liushiwen/PycharmProjects/MyTestFramwoek/UITestObjects/BaseFactory/basepage.py", line 512, in get_alert_text
    return self.driver.switch_to.alert.text
  File "/Users/liushiwen/.local/lib/python3.8/site-packages/selenium/webdriver/remote/switch_to.py", line 55, in alert
    alert.text
  File "/Users/liushiwen/.local/lib/python3.8/site-packages/selenium/webdriver/common/alert.py", line 67, in text
    return self.driver.execute(Command.W3C_GET_ALERT_TEXT)["value"]
  File "/Users/liushiwen/.local/lib/python3.8/site-packages/selenium/webdriver/remote/webdriver.py", line 321, in execute
    self.error_handler.check_response(response)
  File "/Users/liushiwen/.local/lib/python3.8/site-packages/selenium/webdriver/remote/errorhandler.py", line 242, in check_response
    raise exception_class(message, screen, stacktrace)
selenium.common.exceptions.NoAlertPresentException: Message: no such alert
  (Session info: chrome=91.0.4472.164)


2021-07-21 14:16:54,235 : testUserLogin.py : ERROR : Traceback (most recent call last):
  File "/Users/liushiwen/PycharmProjects/MyTestFramwoek/TestCases/UITestCases/testUserLogin.py", line 24, in test_login
    alert_text = self.login.get_alert_text()
  File "/Users/liushiwen/PycharmProjects/MyTestFramwoek/UITestObjects/BaseFactory/basepage.py", line 512, in get_alert_text
    return self.driver.switch_to.alert.text
  File "/Users/liushiwen/.local/lib/python3.8/site-packages/selenium/webdriver/remote/switch_to.py", line 55, in alert
    alert.text
  File "/Users/liushiwen/.local/lib/python3.8/site-packages/selenium/webdriver/common/alert.py", line 67, in text
    return self.driver.execute(Command.W3C_GET_ALERT_TEXT)["value"]
  File "/Users/liushiwen/.local/lib/python3.8/site-packages/selenium/webdriver/remote/webdriver.py", line 321, in execute
    self.error_handler.check_response(response)
  File "/Users/liushiwen/.local/lib/python3.8/site-packages/selenium/webdriver/remote/errorhandler.py", line 242, in check_response
    raise exception_class(message, screen, stacktrace)
selenium.common.exceptions.NoAlertPresentException: Message: no such alert
  (Session info: chrome=91.0.4472.164)


2021-07-21 14:16:54,235 : testUserLogin.py : ERROR : Traceback (most recent call last):
  File "/Users/liushiwen/PycharmProjects/MyTestFramwoek/TestCases/UITestCases/testUserLogin.py", line 24, in test_login
    alert_text = self.login.get_alert_text()
  File "/Users/liushiwen/PycharmProjects/MyTestFramwoek/UITestObjects/BaseFactory/basepage.py", line 512, in get_alert_text
    return self.driver.switch_to.alert.text
  File "/Users/liushiwen/.local/lib/python3.8/site-packages/selenium/webdriver/remote/switch_to.py", line 55, in alert
    alert.text
  File "/Users/liushiwen/.local/lib/python3.8/site-packages/selenium/webdriver/common/alert.py", line 67, in text
    return self.driver.execute(Command.W3C_GET_ALERT_TEXT)["value"]
  File "/Users/liushiwen/.local/lib/python3.8/site-packages/selenium/webdriver/remote/webdriver.py", line 321, in execute
    self.error_handler.check_response(response)
  File "/Users/liushiwen/.local/lib/python3.8/site-packages/selenium/webdriver/remote/errorhandler.py", line 242, in check_response
    raise exception_class(message, screen, stacktrace)
selenium.common.exceptions.NoAlertPresentException: Message: no such alert
  (Session info: chrome=91.0.4472.164)


2021-07-21 14:16:54,235 : testUserLogin.py : ERROR : Traceback (most recent call last):
  File "/Users/liushiwen/PycharmProjects/MyTestFramwoek/TestCases/UITestCases/testUserLogin.py", line 24, in test_login
    alert_text = self.login.get_alert_text()
  File "/Users/liushiwen/PycharmProjects/MyTestFramwoek/UITestObjects/BaseFactory/basepage.py", line 512, in get_alert_text
    return self.driver.switch_to.alert.text
  File "/Users/liushiwen/.local/lib/python3.8/site-packages/selenium/webdriver/remote/switch_to.py", line 55, in alert
    alert.text
  File "/Users/liushiwen/.local/lib/python3.8/site-packages/selenium/webdriver/common/alert.py", line 67, in text
    return self.driver.execute(Command.W3C_GET_ALERT_TEXT)["value"]
  File "/Users/liushiwen/.local/lib/python3.8/site-packages/selenium/webdriver/remote/webdriver.py", line 321, in execute
    self.error_handler.check_response(response)
  File "/Users/liushiwen/.local/lib/python3.8/site-packages/selenium/webdriver/remote/errorhandler.py", line 242, in check_response
    raise exception_class(message, screen, stacktrace)
selenium.common.exceptions.NoAlertPresentException: Message: no such alert
  (Session info: chrome=91.0.4472.164)


2021-07-21 14:16:54,235 : testUserLogin.py : ERROR : Traceback (most recent call last):
  File "/Users/liushiwen/PycharmProjects/MyTestFramwoek/TestCases/UITestCases/testUserLogin.py", line 24, in test_login
    alert_text = self.login.get_alert_text()
  File "/Users/liushiwen/PycharmProjects/MyTestFramwoek/UITestObjects/BaseFactory/basepage.py", line 512, in get_alert_text
    return self.driver.switch_to.alert.text
  File "/Users/liushiwen/.local/lib/python3.8/site-packages/selenium/webdriver/remote/switch_to.py", line 55, in alert
    alert.text
  File "/Users/liushiwen/.local/lib/python3.8/site-packages/selenium/webdriver/common/alert.py", line 67, in text
    return self.driver.execute(Command.W3C_GET_ALERT_TEXT)["value"]
  File "/Users/liushiwen/.local/lib/python3.8/site-packages/selenium/webdriver/remote/webdriver.py", line 321, in execute
    self.error_handler.check_response(response)
  File "/Users/liushiwen/.local/lib/python3.8/site-packages/selenium/webdriver/remote/errorhandler.py", line 242, in check_response
    raise exception_class(message, screen, stacktrace)
selenium.common.exceptions.NoAlertPresentException: Message: no such alert
  (Session info: chrome=91.0.4472.164)


2021-07-21 14:17:47,846 : testUserLogin.py : ERROR : 未捕获到alert事件
2021-07-21 14:17:47,846 : testUserLogin.py : ERROR : 未捕获到alert事件
2021-07-21 14:17:47,846 : testUserLogin.py : ERROR : 未捕获到alert事件
2021-07-21 14:17:47,846 : testUserLogin.py : ERROR : 未捕获到alert事件
2021-07-21 14:17:47,846 : testUserLogin.py : ERROR : 未捕获到alert事件
2021-07-21 14:17:47,846 : testUserLogin.py : ERROR : 未捕获到alert事件
2021-07-21 14:17:47,846 : testUserLogin.py : ERROR : 未捕获到alert事件
2021-07-21 14:17:47,846 : testUserLogin.py : ERROR : 未捕获到alert事件
2021-07-21 14:17:47,846 : testUserLogin.py : ERROR : 未捕获到alert事件
2021-07-21 14:17:47,846 : testUserLogin.py : ERROR : 未捕获到alert事件
2021-07-21 14:17:47,850 : testUserLogin.py : ERROR : Traceback (most recent call last):
  File "/Users/liushiwen/PycharmProjects/MyTestFramwoek/TestCases/UITestCases/testUserLogin.py", line 24, in test_login
    alert_text = self.login.get_alert_text()
  File "/Users/liushiwen/PycharmProjects/MyTestFramwoek/UITestObjects/BaseFactory/basepage.py", line 512, in get_alert_text
    return self.driver.switch_to.alert.text
  File "/Users/liushiwen/.local/lib/python3.8/site-packages/selenium/webdriver/remote/switch_to.py", line 55, in alert
    alert.text
  File "/Users/liushiwen/.local/lib/python3.8/site-packages/selenium/webdriver/common/alert.py", line 67, in text
    return self.driver.execute(Command.W3C_GET_ALERT_TEXT)["value"]
  File "/Users/liushiwen/.local/lib/python3.8/site-packages/selenium/webdriver/remote/webdriver.py", line 321, in execute
    self.error_handler.check_response(response)
  File "/Users/liushiwen/.local/lib/python3.8/site-packages/selenium/webdriver/remote/errorhandler.py", line 242, in check_response
    raise exception_class(message, screen, stacktrace)
selenium.common.exceptions.NoAlertPresentException: Message: no such alert
  (Session info: chrome=91.0.4472.164)


2021-07-21 14:17:47,850 : testUserLogin.py : ERROR : Traceback (most recent call last):
  File "/Users/liushiwen/PycharmProjects/MyTestFramwoek/TestCases/UITestCases/testUserLogin.py", line 24, in test_login
    alert_text = self.login.get_alert_text()
  File "/Users/liushiwen/PycharmProjects/MyTestFramwoek/UITestObjects/BaseFactory/basepage.py", line 512, in get_alert_text
    return self.driver.switch_to.alert.text
  File "/Users/liushiwen/.local/lib/python3.8/site-packages/selenium/webdriver/remote/switch_to.py", line 55, in alert
    alert.text
  File "/Users/liushiwen/.local/lib/python3.8/site-packages/selenium/webdriver/common/alert.py", line 67, in text
    return self.driver.execute(Command.W3C_GET_ALERT_TEXT)["value"]
  File "/Users/liushiwen/.local/lib/python3.8/site-packages/selenium/webdriver/remote/webdriver.py", line 321, in execute
    self.error_handler.check_response(response)
  File "/Users/liushiwen/.local/lib/python3.8/site-packages/selenium/webdriver/remote/errorhandler.py", line 242, in check_response
    raise exception_class(message, screen, stacktrace)
selenium.common.exceptions.NoAlertPresentException: Message: no such alert
  (Session info: chrome=91.0.4472.164)


2021-07-21 14:17:47,850 : testUserLogin.py : ERROR : Traceback (most recent call last):
  File "/Users/liushiwen/PycharmProjects/MyTestFramwoek/TestCases/UITestCases/testUserLogin.py", line 24, in test_login
    alert_text = self.login.get_alert_text()
  File "/Users/liushiwen/PycharmProjects/MyTestFramwoek/UITestObjects/BaseFactory/basepage.py", line 512, in get_alert_text
    return self.driver.switch_to.alert.text
  File "/Users/liushiwen/.local/lib/python3.8/site-packages/selenium/webdriver/remote/switch_to.py", line 55, in alert
    alert.text
  File "/Users/liushiwen/.local/lib/python3.8/site-packages/selenium/webdriver/common/alert.py", line 67, in text
    return self.driver.execute(Command.W3C_GET_ALERT_TEXT)["value"]
  File "/Users/liushiwen/.local/lib/python3.8/site-packages/selenium/webdriver/remote/webdriver.py", line 321, in execute
    self.error_handler.check_response(response)
  File "/Users/liushiwen/.local/lib/python3.8/site-packages/selenium/webdriver/remote/errorhandler.py", line 242, in check_response
    raise exception_class(message, screen, stacktrace)
selenium.common.exceptions.NoAlertPresentException: Message: no such alert
  (Session info: chrome=91.0.4472.164)


2021-07-21 14:17:47,850 : testUserLogin.py : ERROR : Traceback (most recent call last):
  File "/Users/liushiwen/PycharmProjects/MyTestFramwoek/TestCases/UITestCases/testUserLogin.py", line 24, in test_login
    alert_text = self.login.get_alert_text()
  File "/Users/liushiwen/PycharmProjects/MyTestFramwoek/UITestObjects/BaseFactory/basepage.py", line 512, in get_alert_text
    return self.driver.switch_to.alert.text
  File "/Users/liushiwen/.local/lib/python3.8/site-packages/selenium/webdriver/remote/switch_to.py", line 55, in alert
    alert.text
  File "/Users/liushiwen/.local/lib/python3.8/site-packages/selenium/webdriver/common/alert.py", line 67, in text
    return self.driver.execute(Command.W3C_GET_ALERT_TEXT)["value"]
  File "/Users/liushiwen/.local/lib/python3.8/site-packages/selenium/webdriver/remote/webdriver.py", line 321, in execute
    self.error_handler.check_response(response)
  File "/Users/liushiwen/.local/lib/python3.8/site-packages/selenium/webdriver/remote/errorhandler.py", line 242, in check_response
    raise exception_class(message, screen, stacktrace)
selenium.common.exceptions.NoAlertPresentException: Message: no such alert
  (Session info: chrome=91.0.4472.164)


2021-07-21 14:17:47,850 : testUserLogin.py : ERROR : Traceback (most recent call last):
  File "/Users/liushiwen/PycharmProjects/MyTestFramwoek/TestCases/UITestCases/testUserLogin.py", line 24, in test_login
    alert_text = self.login.get_alert_text()
  File "/Users/liushiwen/PycharmProjects/MyTestFramwoek/UITestObjects/BaseFactory/basepage.py", line 512, in get_alert_text
    return self.driver.switch_to.alert.text
  File "/Users/liushiwen/.local/lib/python3.8/site-packages/selenium/webdriver/remote/switch_to.py", line 55, in alert
    alert.text
  File "/Users/liushiwen/.local/lib/python3.8/site-packages/selenium/webdriver/common/alert.py", line 67, in text
    return self.driver.execute(Command.W3C_GET_ALERT_TEXT)["value"]
  File "/Users/liushiwen/.local/lib/python3.8/site-packages/selenium/webdriver/remote/webdriver.py", line 321, in execute
    self.error_handler.check_response(response)
  File "/Users/liushiwen/.local/lib/python3.8/site-packages/selenium/webdriver/remote/errorhandler.py", line 242, in check_response
    raise exception_class(message, screen, stacktrace)
selenium.common.exceptions.NoAlertPresentException: Message: no such alert
  (Session info: chrome=91.0.4472.164)


2021-07-21 14:17:47,850 : testUserLogin.py : ERROR : Traceback (most recent call last):
  File "/Users/liushiwen/PycharmProjects/MyTestFramwoek/TestCases/UITestCases/testUserLogin.py", line 24, in test_login
    alert_text = self.login.get_alert_text()
  File "/Users/liushiwen/PycharmProjects/MyTestFramwoek/UITestObjects/BaseFactory/basepage.py", line 512, in get_alert_text
    return self.driver.switch_to.alert.text
  File "/Users/liushiwen/.local/lib/python3.8/site-packages/selenium/webdriver/remote/switch_to.py", line 55, in alert
    alert.text
  File "/Users/liushiwen/.local/lib/python3.8/site-packages/selenium/webdriver/common/alert.py", line 67, in text
    return self.driver.execute(Command.W3C_GET_ALERT_TEXT)["value"]
  File "/Users/liushiwen/.local/lib/python3.8/site-packages/selenium/webdriver/remote/webdriver.py", line 321, in execute
    self.error_handler.check_response(response)
  File "/Users/liushiwen/.local/lib/python3.8/site-packages/selenium/webdriver/remote/errorhandler.py", line 242, in check_response
    raise exception_class(message, screen, stacktrace)
selenium.common.exceptions.NoAlertPresentException: Message: no such alert
  (Session info: chrome=91.0.4472.164)


2021-07-21 14:17:47,850 : testUserLogin.py : ERROR : Traceback (most recent call last):
  File "/Users/liushiwen/PycharmProjects/MyTestFramwoek/TestCases/UITestCases/testUserLogin.py", line 24, in test_login
    alert_text = self.login.get_alert_text()
  File "/Users/liushiwen/PycharmProjects/MyTestFramwoek/UITestObjects/BaseFactory/basepage.py", line 512, in get_alert_text
    return self.driver.switch_to.alert.text
  File "/Users/liushiwen/.local/lib/python3.8/site-packages/selenium/webdriver/remote/switch_to.py", line 55, in alert
    alert.text
  File "/Users/liushiwen/.local/lib/python3.8/site-packages/selenium/webdriver/common/alert.py", line 67, in text
    return self.driver.execute(Command.W3C_GET_ALERT_TEXT)["value"]
  File "/Users/liushiwen/.local/lib/python3.8/site-packages/selenium/webdriver/remote/webdriver.py", line 321, in execute
    self.error_handler.check_response(response)
  File "/Users/liushiwen/.local/lib/python3.8/site-packages/selenium/webdriver/remote/errorhandler.py", line 242, in check_response
    raise exception_class(message, screen, stacktrace)
selenium.common.exceptions.NoAlertPresentException: Message: no such alert
  (Session info: chrome=91.0.4472.164)


2021-07-21 14:17:47,850 : testUserLogin.py : ERROR : Traceback (most recent call last):
  File "/Users/liushiwen/PycharmProjects/MyTestFramwoek/TestCases/UITestCases/testUserLogin.py", line 24, in test_login
    alert_text = self.login.get_alert_text()
  File "/Users/liushiwen/PycharmProjects/MyTestFramwoek/UITestObjects/BaseFactory/basepage.py", line 512, in get_alert_text
    return self.driver.switch_to.alert.text
  File "/Users/liushiwen/.local/lib/python3.8/site-packages/selenium/webdriver/remote/switch_to.py", line 55, in alert
    alert.text
  File "/Users/liushiwen/.local/lib/python3.8/site-packages/selenium/webdriver/common/alert.py", line 67, in text
    return self.driver.execute(Command.W3C_GET_ALERT_TEXT)["value"]
  File "/Users/liushiwen/.local/lib/python3.8/site-packages/selenium/webdriver/remote/webdriver.py", line 321, in execute
    self.error_handler.check_response(response)
  File "/Users/liushiwen/.local/lib/python3.8/site-packages/selenium/webdriver/remote/errorhandler.py", line 242, in check_response
    raise exception_class(message, screen, stacktrace)
selenium.common.exceptions.NoAlertPresentException: Message: no such alert
  (Session info: chrome=91.0.4472.164)


2021-07-21 14:17:47,850 : testUserLogin.py : ERROR : Traceback (most recent call last):
  File "/Users/liushiwen/PycharmProjects/MyTestFramwoek/TestCases/UITestCases/testUserLogin.py", line 24, in test_login
    alert_text = self.login.get_alert_text()
  File "/Users/liushiwen/PycharmProjects/MyTestFramwoek/UITestObjects/BaseFactory/basepage.py", line 512, in get_alert_text
    return self.driver.switch_to.alert.text
  File "/Users/liushiwen/.local/lib/python3.8/site-packages/selenium/webdriver/remote/switch_to.py", line 55, in alert
    alert.text
  File "/Users/liushiwen/.local/lib/python3.8/site-packages/selenium/webdriver/common/alert.py", line 67, in text
    return self.driver.execute(Command.W3C_GET_ALERT_TEXT)["value"]
  File "/Users/liushiwen/.local/lib/python3.8/site-packages/selenium/webdriver/remote/webdriver.py", line 321, in execute
    self.error_handler.check_response(response)
  File "/Users/liushiwen/.local/lib/python3.8/site-packages/selenium/webdriver/remote/errorhandler.py", line 242, in check_response
    raise exception_class(message, screen, stacktrace)
selenium.common.exceptions.NoAlertPresentException: Message: no such alert
  (Session info: chrome=91.0.4472.164)


2021-07-21 14:17:47,850 : testUserLogin.py : ERROR : Traceback (most recent call last):
  File "/Users/liushiwen/PycharmProjects/MyTestFramwoek/TestCases/UITestCases/testUserLogin.py", line 24, in test_login
    alert_text = self.login.get_alert_text()
  File "/Users/liushiwen/PycharmProjects/MyTestFramwoek/UITestObjects/BaseFactory/basepage.py", line 512, in get_alert_text
    return self.driver.switch_to.alert.text
  File "/Users/liushiwen/.local/lib/python3.8/site-packages/selenium/webdriver/remote/switch_to.py", line 55, in alert
    alert.text
  File "/Users/liushiwen/.local/lib/python3.8/site-packages/selenium/webdriver/common/alert.py", line 67, in text
    return self.driver.execute(Command.W3C_GET_ALERT_TEXT)["value"]
  File "/Users/liushiwen/.local/lib/python3.8/site-packages/selenium/webdriver/remote/webdriver.py", line 321, in execute
    self.error_handler.check_response(response)
  File "/Users/liushiwen/.local/lib/python3.8/site-packages/selenium/webdriver/remote/errorhandler.py", line 242, in check_response
    raise exception_class(message, screen, stacktrace)
selenium.common.exceptions.NoAlertPresentException: Message: no such alert
  (Session info: chrome=91.0.4472.164)


